Workbook

Sheet Clients
A1: Client_ID | B1: Company_Name | C1: Industry | D1: Contract_Type | E1: Region | F1: City | G1: Onboarding_Date | H1: Satisfaction_Score | I1: Tenure_Years | J1: Annual_Contract_Value | K1: Account_Status
A2: CLI-0113 | B2: CloudNine Enterprises | C2: Healthcare | D2: Managed Services | E2: South | F2: Hyderabad | G2: 44281 | H2: 3.2 | I2: 4 | J2: 75000 | K2: Active
A3: CLI-0047 | B3: DigitalForge Services | C3: Government | D3: Managed Services | E3: East | F3: Kolkata | G3: 45171 | H3: 3.1 | I3: 1.6 | J3: 100000 | K3: Active
A4: CLI-0083 | B4: OmniSoft Digital | C4: Media | D4: Annual License | E4: East | F4: Kolkata | G4: 43835 | H4: 4.4 | I4: 5.2 | J4: 300000 | K4: Active
A5: CLI-0111 | B5: CloudNine Enterprises | C5: Banking | D5: Monthly SaaS | E5: West | F5: Ahmedabad | G5: 44775 | H5: 4.9 | I5: 2.7 | J5: 75000 | K5: Active
A6: CLI-0199 | B6: GreenPulse Technologies | C6: Banking | D6: Monthly SaaS | E6: West | F6: Ahmedabad | G6: 44538 | H6: 4.3 | I6: 3.3 | J6: 75000 | K6: Active
A7: CLI-0213 | B7: SwiftCode Solutions | C7: Logistics | D7: Monthly SaaS | E7: West | F7: Surat | G7: 44170 | H7: 3.8 | I7: 4.3 | J7: 500000 | K7: Active
A8: CLI-0042 | B8: NovaTech Group | C8: EdTech | D8: Annual License | E8: West | F8: Surat | G8: 43682 | H8: 3.4 | I8: 5.7 | J8: 750000 | K8: Churned
A9: CLI-0217 | B9: BlueOrbit Systems | C9: EdTech | D9: Multi-Year | E9: East | F9: Kolkata | G9: 43510 | H9: 4.3 | I9: 6.1 | J9: 100000 | K9: Churned
A10: CLI-0070 | B10: SilverEdge Labs | C10: Media | D10: Monthly SaaS | E10: North | F10: Lucknow | G10: 43494 | H10: 2.8 | I10: 6.2 | J10: 300000 | K10: Active
A11: CLI-0115 | B11: DataWeave Corp | C11: Healthcare | D11: Managed Services | E11: East | F11: Patna | G11: 45209 | H11: 4.3 | I11: 1.5 | J11: 100000 | K11: Churned
A12: CLI-0264 | B12: BrightPath Technologies | C12: Insurance | D12: Project-Based | E12: South | F12: Kochi | G12: 43474 | H12: 2.6 | I12: 6.2 | J12: 500000 | K12: Churned
A13: CLI-0219 | B13: OmniSoft Corp | C13: Manufacturing | D13: Managed Services | E13: South | F13: Kochi | G13: 44094 | H13: 3.2 | I13: 4.5 | J13: 100000 | K13: Churned
... A52: CLI-0164 | B52: SilverEdge Corp | C52: Media | D52: Project-Based | E52: West | F52: Pune | G52: 44858 | H52: 3.5 | I52: 2.4 | J52: 200000 | K52: Churned
A53: CLI-0274 | B53: Apex Technologies | C53: EdTech | D53: Project-Based | E53: South | F53: Chennai | G53: 45429 | I53: 0.9 | J53: 300000 | K53: Active
A54: CLI-0271 | B54: CrestLine Systems | C54: Media | D54: Annual License | E54: West | F54: Mumbai | G54: 44343 | H54: 3.2 | I54: 3.8 | J54: 100000 | K54: Active
A55: CLI-0025 | B55: InfraMax Solutions | C55: Retail | D55: Monthly SaaS | E55: West | F55: Pune | G55: 44012 | H55: 4.3 | I55: 4.8 | J55: 500000 | K55: At Risk
A56: CLI-0041 | B56: BrightPath Labs | C56: Logistics | D56: Multi-Year | E56: North | F56: Chandigarh | G56: 43674 | H56: 3.3 | I56: 5.7 | J56: 75000 | K56: Churned
A57: CLI-0029 | B57: InfraMax Corp | C57: Logistics | D57: Monthly SaaS | E57: South | F57: Unspecified | G57: 44327 | H57: 3.4 | I57: 3.9 | J57: 100000 | K57: Active
A58: CLI-0136 | B58: CoreLogic Corp | C58: Telecom | D58: Annual License | E58: North | F58: Chandigarh | G58: 44561 | H58: 4.6 | I58: 3.2 | J58: 50000 | K58: At Risk
A59: CLI-0050 | B59: InfraMax Services | C59: Government | D59: Managed Services | E59: North | F59: Delhi | G59: 45406 | H59: 4.1 | I59: 0.9 | J59: 200000 | K59: Active
A60: CLI-0032 | B60: TechVista Infotech | C60: Retail | D60: Annual License | E60: North | F60: Lucknow | G60: 43914 | H60: 4.9 | I60: 5 | J60: 1000000 | K60: Active
A61: CLI-0161 | B61: Pinnacle Group | C61: Banking | D61: Multi-Year | E61: South | F61: Kochi | G61: 44021 | I61: 4.7 | J61: 75000 | K61: Active
A62: CLI-0044 | B62: Apex Enterprises | C62: EdTech | D62: Multi-Year | E62: West | F62: Pune | G62: 44192 | H62: 3.4 | I62: 4.3 | J62: 200000 | K62: Active
A63: CLI-0085 | B63: OmniSoft Solutions | C63: Healthcare | D63: Monthly SaaS | E63: West | F63: Surat | G63: 44460 | H63: 3.5 | I63: 3.5 | J63: 150000 | K63: Churned
A64: CLI-0065 | B64: Zenith Infotech | C64: Insurance | D64: Monthly SaaS | E64: West | F64: Ahmedabad | G64: 44831 | I64: 2.5 | J64: 750000 | K64: At Risk
A65: CLI-0037 | B65: GreenPulse Labs | C65: Insurance | D65: Annual License | E65: West | F65: Ahmedabad | G65: 44835 | H65: 3.5 | I65: 2.5 | J65: 100000 | K65: Churned
A66: CLI-0172 | B66: InfraMax Group | C66: Banking | D66: Monthly SaaS | E66: North | F66: Delhi | G66: 45040 | H66: 4.2 | I66: 1.9 | J66: 100000 | K66: Active
A67: CLI-0112 | B67: Apex Systems | C67: Government | D67: Project-Based | E67: North | F67: Chandigarh | G67: 43603 | H67: 4.1 | I67: 5.9 | J67: 300000 | K67: Active
A68: CLI-0177 | B68: BrightPath Labs | C68: Logistics | D68: Annual License | E68: South | F68: Chennai | G68: 44036 | H68: 4.5 | I68: 4.7 | J68: 75000 | K68: Active
A69: CLI-0016 | B69: SwiftCode Technologies | C69: Banking | D69: Managed Services | E69: North | F69: Delhi | G69: 45363 | H69: 3.1 | I69: 1.1 | J69: 500000 | K69: Active
A70: CLI-0200 | B70: CrestLine Services | C70: Healthcare | D70: Managed Services | E70: North | F70: Chandigarh | G70: 44983 | H70: 2.6 | I70: 2.1 | J70: 50000 | K70: Active
A71: CLI-0153 | B71: DigitalForge Infotech | C71: EdTech | D71: Monthly SaaS | E71: North | F71: Chandigarh | G71: 45385 | H71: 4.4 | I71: 1 | J71: 750000 | K71: At Risk
A72: CLI-0292 | B72: SilverEdge Solutions | C72: Retail | D72: Managed Services | E72: South | F72: Chennai | G72: 44755 | H72: 4.7 | I72: 2.7 | J72: 100000 | K72: Active
A73: CLI-0082 | B73: BrightPath Group | C73: Manufacturing | D73: Multi-Year | E73: West | F73: Pune | G73: 45201 | H73: 4.6 | I73: 1.5 | J73: 300000 | K73: Active
A74: CLI-0165 | B74: Zenith Labs | C74: EdTech | D74: Monthly SaaS | E74: North | F74: Delhi | G74: 43476 | H74: 3.6 | I74: 6.2 | J74: 200000 | K74: Active
A75: CLI-0273 | B75: SwiftCode Group | C75: Logistics | D75: Annual License | E75: East | F75: Bhubaneswar | G75: 45275 | H75: 3.3 | I75: 1.3 | J75: 300000 | K75: Active
A76: CLI-0076 | B76: Pinnacle Solutions | C76: Retail | D76: Annual License | E76: East | F76: Bhubaneswar | G76: 44671 | H76: 2.9 | I76: 2.9 | J76: 50000 | K76: Active
... A80: CLI-0284 | B80: SilverEdge Infotech | C80: Logistics | D80: Monthly SaaS | E80: East | F80: Bhubaneswar | G80: 44857 | H80: 4.7 | I80: 2.4 | J80: 750000 | K80: Active
A81: CLI-0086 | B81: DigitalForge Group | C81: Telecom | D81: Annual License | E81: South | F81: Kochi | G81: 44693 | I81: 2.9 | J81: 150000 | K81: Active
...

Sheet Finance_Expenses
A1: Expense_ID | B1: Department | C1: Category | D1: Vendor | E1: Amount_INR | F1: Budget_Allocated_INR | G1: Recomputed_Variance_INR | H1: Old_Variance_INR | I1: Expense_Date | J1: Approval_Status | K1: Payment_Mode | L1: Fiscal_Year | M1: Remarks | N1: Amount_Type_Flag | O1: High_Value_Pending_Rejected_Flag
A2: EXP-00594 | B2: Unspecified | C2: Cloud Infrastructure | D2: Slack | E2: 209189 | F2: 170793.17 | G2: =IF(Table13[[#This Row],[Budget_Allocated_INR]]="","",Table13[[#This Row],[Amount_INR]]-Table13[[#This Row],[Budget_Allocated_INR]]) -> 38395.83 | H2: 38395.83 | I2: 45126 | J2: Pending | K2: Vendor Credit | L2: FY2023-2024 | M2: Under review | N2: Expense | O2: Flag: High-Value Pending
A3: EXP-00495 | B3: Operations | C3: Utilities | D3: HubSpot | E3: 6214 | F3: 7523.05 | G3: =IF(Table13[[#This Row],[Budget_Allocated_INR]]="","",Table13[[#This Row],[Amount_INR]]-Table13[[#This Row],[Budget_Allocated_INR]]) -> -1309.05 | H3: -1309.05 | I3: 45209 | J3: Approved | K3: Bank Transfer | L3: FY2023-2024 | M3: Recurring | N3: Expense
A4: EXP-00587 | B4: Sales | C4: Marketing Spend | D4: SAP | E4: 499533 | F4: 550589.56 | G4: =IF(Table13[[#This Row],[Budget_Allocated_INR]]="","",Table13[[#This Row],[Amount_INR]]-Table13[[#This Row],[Budget_Allocated_INR]]) -> -51056.56 | H4: -51056.56 | I4: 45310 | J4: Approved | K4: Bank Transfer | L4: FY2023-2024 | M4: Recurring | N4: Expense
A5: EXP-00178 | B5: Finance | C5: Utilities | D5: Infosys | E5: 403234 | F5: 426617.54 | G5: =IF(Table13[[#This Row],[Budget_Allocated_INR]]="","",Table13[[#This Row],[Amount_INR]]-Table13[[#This Row],[Budget_Allocated_INR]]) -> -23383.54 | H5: -23383.54 | I5: 45732 | J5: Approved | K5: Bank Transfer | L5: FY2024-2025 | N5: Expense
A6: EXP-00869 | B6: Unspecified | C6: Cloud Infrastructure | D6: TCS | E6: 187461 | F6: 156297.94 | G6: =IF(Table13[[#This Row],[Budget_Allocated_INR]]="","",Table13[[#This Row],[Amount_INR]]-Table13[[#This Row],[Budget_Allocated_INR]]) -> 31163.06 | H6: 31163.06 | I6: 44963 | J6: Approved | K6: Credit Card | L6: FY2022-2023 | N6: Expense
A7: EXP-00674 | B7: Sales | C7: Hardware | D7: TCS | E7: 352393 | F7: 449410.33 | G7: =IF(Table13[[#This Row],[Budget_Allocated_INR]]="","",Table13[[#This Row],[Amount_INR]]-Table13[[#This Row],[Budget_Allocated_INR]]) -> -97017.33 | H7: -97017.33 | I7: 45365 | J7: Approved | K7: Bank Transfer | L7: FY2023-2024 | N7: Expense
A8: EXP-00181 | B8: Engineering | C8: Hardware | D8: Slack | E8: 361946 | F8: 354476.37 | G8: =IF(Table13[[#This Row],[Budget_Allocated_INR]]="","",Table13[[#This Row],[Amount_INR]]-Table13[[#This Row],[Budget_Allocated_INR]]) -> 7469.63 | H8: 7469.63 | I8: 45152 | J8: Pending | K8: Vendor Credit | L8: FY2023-2024 | M8: Urgent | N8: Expense | O8: Flag: High-Value Pending
A9: EXP-00277 | B9: Support | C9: Office Supplies | D9: Wipro | E9: 398503 | F9: 438557.67 | G9: =IF(Table13[[#This Row],[Budget_Allocated_INR]]="","",Table13[[#This Row],[Amount_INR]]-Table13[[#This Row],[Budget_Allocated_INR]]) -> -40054.67 | H9: -40054.67 | I9: 45145 | J9: Approved | K9: Credit Card | L9: FY2023-2024 | N9: Expense
A10: EXP-00515 | B10: Support | C10: Consulting Fees | D10: Oracle | E10: 345565 | F10: 382355.25 | G10: =IF(Table13[[#This Row],[Budget_Allocated_INR]]="","",Table13[[#This Row],[Amount_INR]]-Table13[[#This Row],[Budget_Allocated_INR]]) -> -36790.25 | H10: -36790.25 | I10: 45437 | J10: Approved | K10: Vendor Credit | L10: FY2024-2025 | M10: Duplicate entry | N10: Expense
A11: EXP-00339 | B11: Engineering | C11: Hardware | D11: HubSpot | E11: 441930 | F11: 426169.24 | G11: =IF(Table13[[#This Row],[Budget_Allocated_INR]]="","",Table13[[#This Row],[Amount_INR]]-Table13[[#This Row],[Budget_Allocated_INR]]) -> 15760.76 | H11: 15760.76 | I11: 45740 | J11: Approved | K11: Credit Card | L11: FY2024-2025 | M11: Under review | N11: Expense
A12: EXP-00555 | B12: Unspecified | C12: Office Supplies | D12: SAP | E12: 304214 | F12: 345611.18 | G12: =IF(Table13[[#This Row],[Budget_Allocated_INR]]="","",Table13[[#This Row],[Amount_INR]]-Table13[[#This Row],[Budget_Allocated_INR]]) -> -41397.18 | H12: -41397.18 | I12: 45689 | J12: Approved | K12: Bank Transfer | L12: FY2024-2025 | M12: Recurring | N12: Expense
A13: EXP-00803 | B13: Support | C13: Travel | D13: Freshdesk | E13: 65791 | F13: 59739.7 | G13: =IF(Table13[[#This Row],[Budget_Allocated_INR]]="","",Table13[[#This Row],[Amount_INR]]-Table13[[#This Row],[Budget_Allocated_INR]]) -> 6051.3 | H13: 6051.3 | I13: 45346 | J13: Approved | K13: Petty Cash | L13: FY2023-2024 | M13: Under review | N13: Expense
A14: EXP-00875 | B14: Engineering | C14: Software Licenses | D14: Google Cloud | E14: 49237 | G14: =IF(Table13[[#This Row],[Budget_Allocated_INR]]="","",Table13[[#This Row],[Amount_INR]]-Table13[[#This Row],[Budget_Allocated_INR]]) | H14: 7036.11 | I14: 45457 | J14: Pending | K14: Petty Cash | L14: FY2024-2025 | M14: Duplicate entry | N14: Expense
A15: EXP-00691 | B15: HR | C15: Office Supplies | D15: TCS | E15: 365283 | F15: 359381.54 | G15: =IF(Table13[[#This Row],[Budget_Allocated_INR]]="","",Table13[[#This Row],[Amount_INR]]-Table13[[#This Row],[Budget_Allocated_INR]]) -> 5901.46 | H15: 5901.46 | I15: 45645 | J15: Approved | K15: Credit Card | L15: FY2024-2025 | N15: Expense
A16: EXP-00233 | B16: HR | C16: Consulting Fees | D16: Google Cloud | E16: 201346 | F16: 197464.53 | G16: =IF(Table13[[#This Row],[Budget_Allocated_INR]]="","",Table13[[#This Row],[Amount_INR]]-Table13[[#This Row],[Budget_Allocated_INR]]) -> 3881.47 | I16: 45719 | J16: Pending | K16: Bank Transfer | L16: FY2024-2025 | M16: Under review | N16: Expense | O16: Flag: High-Value Pending
A17: EXP-00071 | B17: Sales | C17: Hardware | D17: HubSpot | E17: 375484 | F17: 303740.88 | G17: =IF(Table13[[#This Row],[Budget_Allocated_INR]]="","",Table13[[#This Row],[Amount_INR]]-Table13[[#This Row],[Budget_Allocated_INR]]) -> 71743.12 | H17: 71743.12 | I17: 45454 | J17: Pending | K17: Bank Transfer | L17: FY2024-2025 | M17: One-time | N17: Expense | O17: Flag: High-Value Pending
A18: EXP-00860 | B18: Operations | C18: Cloud Infrastructure | D18: Wipro | E18: 91274 | F18: 117271.6 | G18: =IF(Table13[[#This Row],[Budget_Allocated_INR]]="","",Table13[[#This Row],[Amount_INR]]-Table13[[#This Row],[Budget_Allocated_INR]]) -> -25997.6 | H18: -25997.6 | I18: 45367 | J18: Approved | K18: Petty Cash | L18: FY2023-2024 | N18: Expense
A19: EXP-00607 | B19: Finance | C19: Hardware | D19: Jira | E19: 58546 | F19: 54790.73 | G19: =IF(Table13[[#This Row],[Budget_Allocated_INR]]="","",Table13[[#This Row],[Amount_INR]]-Table13[[#This Row],[Budget_Allocated_INR]]) -> 3755.27 | H19: 3755.27 | I19: 45324 | J19: Approved | K19: Petty Cash | L19: FY2023-2024 | M19: Under review | N19: Expense
A20: EXP-00651 | B20: Unspecified | C20: Marketing Spend | D20: SAP | E20: 10904 | F20: 13676.8 | G20: =IF(Table13[[#This Row],[Budget_Allocated_INR]]="","",Table13[[#This Row],[Amount_INR]]-Table13[[#This Row],[Budget_Allocated_INR]]) -> -2772.8 | H20: -2772.8 | I20: 44973 | J20: Approved | K20: Vendor Credit | L20: FY2022-2023 | M20: Duplicate entry | N20: Expense
A21: EXP-00652 | B21: Operations | C21: Utilities | D21: AWS | E21: 65481 | F21: 81303.61 | G21: =IF(Table13[[#This Row],[Budget_Allocated_INR]]="","",Table13[[#This Row],[Amount_INR]]-Table13[[#This Row],[Budget_Allocated_INR]]) -> -15822.61 | H21: -15822.61 | I21: 44962 | J21: Pending | K21: Vendor Credit | L21: FY2022-2023 | M21: Duplicate entry | N21: Expense
A22: EXP-00369 | B22: Marketing | C22: Marketing Spend | D22: HubSpot | E22: 66000 | F22: 78840.27 | G22: =IF(Table13[[#This Row],[Budget_Allocated_INR]]="","",Table13[[#This Row],[Amount_INR]]-Table13[[#This Row],[Budget_Allocated_INR]]) -> -12840.27 | H22: -12840.27 | I22: 45341 | J22: Approved | K22: Credit Card | L22: FY2023-2024 | M22: Under review | N22: Expense
A23: EXP-00721 | B23: Finance | C23: Office Supplies | D23: Slack | E23: 32147 | F23: 36235.03 | G23: =IF(Table13[[#This Row],[Budget_Allocated_INR]]="","",Table13[[#This Row],[Amount_INR]]-Table13[[#This Row],[Budget_Allocated_INR]]) -> -4088.03 | H23: -4088.03 | I23: 45247 | J23: Approved | K23: Credit Card | L23: FY2023-2024 | N23: Expense
A24: EXP-00390 | B24: Unspecified | C24: Consulting Fees | D24: Wipro | E24: 312310 | F24: 339411.41 | G24: =IF(Table13[[#This Row],[Budget_Allocated_INR]]="","",Table13[[#This Row],[Amount_INR]]-Table13[[#This Row],[Budget_Allocated_INR]]) -> -27101.41 | H24: -27101.41 | I24: 45270 | J24: Pending | K24: Bank Transfer | L24: FY2023-2024 | M24: Duplicate entry | N24: Expense | O24: Flag: High-Value Pending
A25: EXP-00520 | B25: HR | C25: Utilities | D25: Infosys | E25: 145866 | F25: 176369.11 | G25: =IF(Table13[[#This Row],[Budget_Allocated_INR]]="","",Table13[[#This Row],[Amount_INR]]-Table13[[#This Row],[Budget_Allocated_INR]]) -> -30503.11 | H25: -30503.11 | I25: 45589 | J25: Approved | K25: Petty Cash | L25: FY2024-2025 | M25: Recurring | N25: Expense
A26: EXP-00971 | B26: Finance | C26: Training | D26: Oracle | E26: -270391 | F26: 224861.48 | G26: =IF(Table13[[#This Row],[Budget_Allocated_INR]]="","",Table13[[#This Row],[Amount_INR]]-Table13[[#This Row],[Budget_Allocated_INR]]) -> -495252.48 | H26: 45529.52 | I26: 44992 | J26: Approved | K26: Credit Card | L26: FY2022-2023 | M26: Duplicate entry | N26: Credit/Refund
A27: EXP-00411 | B27: HR | C27: Hardware | D27: Microsoft Azure | E27: 410046 | F27: 483620.72 | G27: =IF(Table13[[#This Row],[Budget_Allocated_INR]]="","",Table13[[#This Row],[Amount_INR]]-Table13[[#This Row],[Budget_Allocated_INR]]) -> -73574.72 | H27: -73574.72 | I27: 45456 | J27: Approved | K27: Petty Cash | L27: FY2024-2025 | N27: Expense
A28: EXP-00354 | B28: Sales | C28: Salaries | D28: Oracle | E28: 406494 | G28: =IF(Table13[[#This Row],[Budget_Allocated_INR]]="","",Table13[[#This Row],[Amount_INR]]-Table13[[#This Row],[Budget_Allocated_INR]]) | H28: -13532 | I28: 45553 | J28: Approved | K28: Credit Card | L28: FY2024-2025 | M28: Recurring | N28: Expense
A29: EXP-00600 | B29: Engineering | C29: Travel | D29: Zoom | E29: 66859 | F29: 75521.94 | G29: =IF(Table13[[#This Row],[Budget_Allocated_INR]]="","",Table13[[#This Row],[Amount_INR]]-Table13[[#This Row],[Budget_Allocated_INR]]) -> -8662.94 | H29: -8662.94 | I29: 45442 | J29: Approved | K29: Petty Cash | L29: FY2024-2025 | N29: Expense
A30: EXP-00034 | B30: Support | C30: Consulting Fees | D30: Oracle | E30: 389612 | F30: 356713.15 | G30: =IF(Table13[[#This Row],[Budget_Allocated_INR]]="","",Table13[[#This Row],[Amount_INR]]-Table13[[#This Row],[Budget_Allocated_INR]]) -> 32898.85 | H30: 32898.85 | I30: 45486 | J30: Pending | K30: Petty Cash | L30: FY2024-2025 | N30: Expense | O30: Flag: High-Value Pending
A31: EXP-00200 | B31: Sales | C31: Salaries | D31: TCS | E31: 397643 | F31: 366588.32 | G31: =IF(Table13[[#This Row],[Budget_Allocated_INR]]="","",Table13[[#This Row],[Amount_INR]]-Table13[[#This Row],[Budget_Allocated_INR]]) -> 31054.68 | I31: 45309 | J31: Pending | K31: Petty Cash | L31: FY2023-2024 | N31: Expense | O31: Flag: High-Value Pending
A32: EXP-00925 | B32: Sales | C32: Software Licenses | D32: Google Cloud | E32: 367122 | F32: 465065.53 | G32: =IF(Table13[[#This Row],[Budget_Allocated_INR]]="","",Table13[[#This Row],[Amount_INR]]-Table13[[#This Row],[Budget_Allocated_INR]]) -> -97943.53 | H32: -97943.53 | I32: 45084 | J32: Pending | K32: Credit Card | L32: FY2023-2024 | M32: One-time | N32: Expense | O32: Flag: High-Value Pending
A33: EXP-00546 | B33: Marketing | C33: Travel | D33: Adobe | E33: 65667 | F33: 72499.12 | G33: =IF(Table13[[#This Row],[Budget_Allocated_INR]]="","",Table13[[#This Row],[Amount_INR]]-Table13[[#This Row],[Budget_Allocated_INR]]) -> -6832.12 | H33: -6832.12 | I33: 45077 | J33: Approved | K33: Petty Cash | L33: FY2023-2024 | N33: Expense
A34: EXP-00602 | B34: Unspecified | C34: Salaries | D34: Wipro | E34: 350446 | F34: 293167.5 | G34: =IF(Table13[[#This Row],[Budget_Allocated_INR]]="","",Table13[[#This Row],[Amount_INR]]-Table13[[#This Row],[Budget_Allocated_INR]]) -> 57278.5 | H34: 57278.5 | I34: 45395 | J34: Approved | K34: Vendor Credit | L34: FY2024-2025 | N34: Expense
A35: EXP-00083 | B35: Support | C35: Maintenance | D35: Wipro | E35: 215496 | F35: 269360.68 | G35: =IF(Table13[[#This Row],[Budget_Allocated_INR]]="","",Table13[[#This Row],[Amount_INR]]-Table13[[#This Row],[Budget_Allocated_INR]]) -> -53864.68 | I35: 45427 | J35: Rejected | K35: Petty Cash | L35: FY2024-2025 | M35: Duplicate entry | N35: Expense | O35: Flag: High-Value Pending
A36: EXP-00750 | B36: Sales | C36: Recruitment | D36: Freshdesk | E36: 7227 | F36: 9023.9 | G36: =IF(Table13[[#This Row],[Budget_Allocated_INR]]="","",Table13[[#This Row],[Amount_INR]]-Table13[[#This Row],[Budget_Allocated_INR]]) -> -1796.9 | H36: -1796.9 | I36: 45131 | J36: Approved | K36: Vendor Credit | L36: FY2023-2024 | N36: Expense
A37: EXP-00172 | B37: Operations | C37: Travel | D37: AWS | E37: 481644 | F37: 431586.58 | G37: =IF(Table13[[#This Row],[Budget_Allocated_INR]]="","",Table13[[#This Row],[Amount_INR]]-Table13[[#This Row],[Budget_Allocated_INR]]) -> 50057.42 | H37: 50057.42 | I37: 45338 | J37: Approved | K37: Vendor Credit | L37: FY2023-2024 | M37: Urgent | N37: Expense
A38: EXP-00531 | B38: Sales | C38: Recruitment | D38: AWS | E38: -214583 | F38: 220195.61 | G38: =IF(Table13[[#This Row],[Budget_Allocated_INR]]="","",Table13[[#This Row],[Amount_INR]]-Table13[[#This Row],[Budget_Allocated_INR]]) -> -434778.61 | H38: -5612.61 | I38: 45157 | J38: Approved | K38: Petty Cash | L38: FY2023-2024 | N38: Credit/Refund
A39: EXP-00337 | B39: Sales | C39: Utilities | D39: HubSpot | E39: 71717 | F39: 89231.77 | G39: =IF(Table13[[#This Row],[Budget_Allocated_INR]]="","",Table13[[#This Row],[Amount_INR]]-Table13[[#This Row],[Budget_Allocated_INR]]) -> -17514.77 | H39: -17514.77 | I39: 45573 | J39: Approved | K39: Credit Card | L39: FY2024-2025 | M39: Urgent | N39: Expense
A40: EXP-00832 | B40: Engineering | C40: Training | D40: Infosys | E40: 352092 | F40: 424330.22 | G40: =IF(Table13[[#This Row],[Budget_Allocated_INR]]="","",Table13[[#This Row],[Amount_INR]]-Table13[[#This Row],[Budget_Allocated_INR]]) -> -72238.22 | H40: -72238.22 | I40: 45540 | J40: Approved | K40: Bank Transfer | L40: FY2024-2025 | M40: One-time | N40: Expense
...

Sheet Marketing_Campaigns
A1: Campaign_ID | B1: Campaign_Name | C1: Channel | D1: Campaign_Type | E1: Start_Date | F1: End_Date | G1: Budget_INR | H1: Impressions | I1: Clicks | J1: MQLs | K1: SQLs | L1: Conversions | M1: CTR_Percent | N1: Cost_Per_Click | O1: Customer_Acquisition_Cost | P1: Target_Region | Q1: Target_Industry
A2: CAMP-0116 | B2: Q2-2023 SecureNet Suite Retargeting | C2: Google Ads | D2: Retargeting | E2: 45027 | F2: 45089 | G2: 751318 | H2: 125501 | I2: 8720 | J2: 2000 | K2: 453 | L2: 158 | M2: 6.95 | N2: 86.16 | O2: 4755.18 | P2: North | Q2: Telecom
A3: CAMP-0035 | B3: Q2-2023 AnalyticsEdge Retargeting | C3: Social Media | D3: Lead Generation | E3: 45470 | F3: 45529 | G3: 931769 | H3: 404277 | I3: 28305 | J3: 3218 | K3: 614 | L3: 177 | M3: 7 | N3: 32.92 | O3: 5264.23 | P3: West | Q3: Manufacturing
A4: CAMP-0127 | B4: Q4-2023 AnalyticsEdge Product Launch | C4: SEO | D4: Brand Awareness | E4: 45082 | F4: 45135 | G4: 1330883 | H4: 169252 | I4: 9199 | J4: 1321 | K4: 320 | L4: 124 | M4: 5.44 | N4: 144.68 | O4: 10732.93 | P4: All Regions | Q4: EdTech
A5: CAMP-0115 | B5: Q4-2024 AI Insights Module Retargeting | C5: Webinar | D5: Brand Awareness | E5: 45529 | F5: 45604 | G5: 1055991 | H5: 167737 | I5: 2658 | J5: 164 | K5: 24 | L5: 6 | M5: 1.58 | N5: 397.29 | O5: 175998.5 | P5: Unspecified | Q5: Retail
A6: CAMP-0111 | B6: Q1-2024 SecureNet Suite Retargeting | C6: Webinar | D6: Lead Generation | E6: 45244 | F6: 45296 | G6: 576586 | H6: 352957 | I6: 18568 | J6: 3933 | K6: 1690 | L6: 470 | M6: 5.26 | N6: 31.05 | O6: 1226.78 | P6: All Regions | Q6: Telecom
A7: CAMP-0123 | B7: Q1-2024 CloudShift Platform Event Promotion | C7: LinkedIn | D7: Brand Awareness | E7: 45317 | F7: 45405 | G7: 99142 | H7: 23806 | I7: 697 | J7: 96 | K7: 16 | L7: 3 | M7: 2.93 | N7: 142.24 | O7: 33047.33 | P7: East | Q7: Telecom
A8: CAMP-0086 | B8: Q2-2023 AnalyticsEdge Product Launch | C8: SEO | D8: Brand Awareness | E8: 45203 | F8: 45278 | G8: 1296128 | H8: 325772 | I8: 9541 | J8: 1855 | K8: 438 | L8: 153 | M8: 2.93 | N8: 135.85 | O8: 8471.42 | P8: West | Q8: Retail
A9: CAMP-0039 | B9: Q3-2025 DevOps Accelerator Event Promotion | C9: Social Media | D9: Lead Generation | E9: 45661 | F9: 45746 | G9: 1268589 | H9: 152974 | I9: 10540 | J9: 2346 | K9: 955 | L9: 280 | M9: 6.89 | N9: 120.36 | O9: 4530.68 | P9: West | Q9: Banking
A10: CAMP-0016 | B10: Q3-2023 DevOps Accelerator Brand Awareness | C10: LinkedIn | D10: Retargeting | E10: 45483 | F10: 45535 | G10: 616140 | H10: 384535 | I10: 19957 | J10: 3229 | K10: 1357 | L10: 235 | M10: 5.19 | N10: 30.87 | O10: 2621.87 | P10: North | Q10: All Industries
A11: CAMP-0043 | B11: Q4-2025 AI Insights Module Brand Awareness | C11: Content Marketing | D11: Event Promotion | E11: 45215 | F11: 45241 | G11: 1208048 | H11: 11982 | I11: 195 | J11: 24 | K11: 8 | L11: 1 | M11: 1.63 | N11: 6195.12 | O11: 1208048 | P11: All Regions | Q11: Healthcare
A12: CAMP-0124 | B12: Q2-2025 SecureNet Suite Brand Awareness | C12: Social Media | D12: Event Promotion | E12: 45505 | F12: 45530 | G12: 1362761 | H12: 48086 | I12: 2575 | J12: 481 | K12: 145 | L12: 51 | M12: 5.35 | N12: 529.23 | O12: 26720.8 | P12: All Regions | Q12: Government
A13: CAMP-0053 | B13: Q2-2025 AI Insights Module Product Launch | C13: Google Ads | D13: Lead Generation | E13: 45352 | F13: 45375 | G13: 487709 | H13: 284841 | I13: 10450 | J13: 1086 | K13: 426 | L13: 97 | M13: 3.67 | N13: 46.67 | O13: 5027.93 | P13: West | Q13: All Industries
... A26: CAMP-0099 | B26: Q2-2025 DevOps Accelerator Brand Awareness | C26: Content Marketing | D26: Lead Generation | E26: 45503 | F26: 45518 | G26: 909983 | H26: 246287 | I26: 13286 | J26: 2769 | K26: 1258 | L26: 134 | M26: 5.39 | N26: 68.49 | O26: 6790.92 | P26: All Regions | Q26: Media
A27: CAMP-0077 | B27: Q4-2024 DataVault Pro Brand Awareness | C27: Google Ads | D27: Brand Awareness | E27: 45130 | F27: 45145 | G27: 639700 | H27: 91607 | I27: =ROUND(Table14[[#This Row],[Impressions]]*(Table14[[#This Row],[CTR_Percent]]/100),0) -> 6110 | J27: 562 | K27: 244 | L27: 75 | M27: 6.67 | N27: 104.65 | O27: 8529.33 | P27: All Regions | Q27: Manufacturing
A28: CAMP-0054 | B28: Q1-2024 AnalyticsEdge Lead Generation | C28: LinkedIn | D28: Event Promotion | E28: 45655 | F28: 45672 | G28: 118248 | H28: 168771 | I28: 5692 | J28: 378 | K28: 98 | L28: 16 | M28: 3.37 | N28: 20.77 | O28: 7390.5 | P28: North | Q28: Government
A29: CAMP-0112 | B29: Q2-2025 SecureNet Suite Brand Awareness | C29: Content Marketing | D29: Lead Generation | E29: 45515 | F29: 45547 | G29: 1084235 | H29: 244228 | I29: 18533 | J29: 1202 | K29: 329 | L29: 117 | M29: 7.59 | N29: 58.5 | O29: 9266.97 | P29: South | Q29: Logistics
A30: CAMP-0032 | B30: Q2-2025 AnalyticsEdge Product Launch | C30: LinkedIn | D30: Product Launch | E30: 45233 | F30: 45314 | G30: 1256395 | H30: 170300 | I30: 1941 | J30: 98 | K30: 37 | L30: 7 | M30: 1.14 | N30: 647.29 | O30: 179485 | P30: All Regions | Q30: Logistics
A31: CAMP-0042 | B31: Q4-2025 CloudShift Platform Retargeting | C31: Email | D31: Brand Awareness | E31: 44981 | F31: 45056 | G31: 1454862 | H31: 34159 | I31: 392 | J31: 24 | K31: 5 | L31: 1 | M31: 1.15 | N31: 3711.38 | O31: 1454862 | P31: East | Q31: Unspecified
A32: CAMP-0080 | B32: Q3-2024 AnalyticsEdge Lead Generation | C32: Social Media | D32: Product Launch | E32: 45028 | F32: 45109 | G32: 880836 | H32: 82670 | I32: 1430 | J32: 232 | K32: 88 | L32: 31 | M32: 1.73 | N32: 615.97 | O32: 28414.06 | P32: West | Q32: Logistics
A33: CAMP-0084 | B33: Q1-2024 AI Insights Module Retargeting | C33: SEO | D33: Product Launch | E33: 44984 | F33: 45038 | G33: 1392111 | H33: 327634 | I33: 23553 | J33: 3422 | K33: 1332 | L33: 222 | M33: 7.19 | N33: 59.11 | O33: 6270.77 | P33: North | Q33: Unspecified
A34: CAMP-0089 | B34: Q1-2024 AI Insights Module Lead Generation | C34: LinkedIn | D34: Product Launch | E34: 45193 | F34: 45220 | G34: 527447 | H34: 280933 | I34: 6027 | J34: 1165 | K34: 553 | L34: 147 | M34: 2.15 | N34: 87.51 | O34: 3588.07 | P34: All Regions | Q34: Manufacturing
A35: CAMP-0146 | B35: Q1-2025 SecureNet Suite Lead Generation | C35: LinkedIn | D35: Product Launch | E35: 45324 | F35: 45387 | G35: 222732 | H35: 463669 | I35: 27503 | J35: 5863 | K35: 953 | L35: 228 | M35: 5.93 | N35: 8.1 | O35: 976.89 | P35: South | Q35: Unspecified
A36: CAMP-0092 | B36: Q1-2024 DevOps Accelerator Lead Generation | C36: LinkedIn | D36: Lead Generation | E36: 44975 | F36: 45065 | G36: 273094 | H36: 235281 | I36: 8812 | J36: 1911 | K36: 683 | L36: 134 | M36: 3.75 | N36: 30.99 | O36: 2038.01 | P36: East | Q36: Unspecified
A37: CAMP-0034 | B37: Q4-2023 DevOps Accelerator Event Promotion | C37: Social Media | D37: Product Launch | E37: 45379 | F37: 45448 | G37: 1009931 | H37: 236770 | I37: 9413 | J37: 2259 | K37: 934 | L37: 287 | M37: 3.98 | N37: 107.29 | O37: 3518.92 | P37: North | Q37: Government
A38: CAMP-0059 | B38: Q4-2025 SecureNet Suite Event Promotion | C38: Social Media | D38: Lead Generation | E38: 45227 | F38: 45259 | G38: 584326 | H38: 42908 | I38: 1663 | J38: 270 | K38: 88 | L38: 16 | M38: 3.88 | N38: 351.37 | O38: 36520.38 | P38: North | Q38: Logistics
A39: CAMP-0003 | B39: Q4-2023 SecureNet Suite Product Launch | C39: LinkedIn | D39: Lead Generation | E39: 45634 | F39: 45675 | G39: 1047835 | H39: 496775 | I39: 27684 | J39: 6540 | K39: 2450 | L39: 458 | M39: 5.57 | N39: 37.85 | O39: 2287.85 | P39: West | Q39: Manufacturing
A40: CAMP-0026 | B40: Q1-2024 CloudShift Platform Product Launch | C40: Google Ads | D40: Retargeting | E40: 45572 | F40: 45647 | G40: 90065 | H40: 309321 | I40: =ROUND(Table14[[#This Row],[Impressions]]*(Table14[[#This Row],[CTR_Percent]]/100),0) -> 4640 | J40: 470 | K40: 199 | L40: 76 | M40: 1.5 | N40: 19.35 | O40: 1185.07 | P40: East | Q40: Unspecified
A41: CAMP-0147 | B41: Q1-2024 AI Insights Module Brand Awareness | C41: Trade Show | D41: Brand Awareness | E41: 45173 | F41: 45213 | G41: 810049 | H41: 24326 | I41: 433 | J41: 56 | K41: 12 | L41: 1 | M41: 1.78 | N41: 1870.78 | O41: 810049 | P41: Unspecified | Q41: Government
A42: CAMP-0014 | B42: Q1-2023 DataVault Pro Brand Awareness | C42: Email | D42: Brand Awareness | E42: 45160 | F42: 45195 | G42: 120003 | H42: 302403 | I42: =ROUND(Table14[[#This Row],[Impressions]]*(Table14[[#This Row],[CTR_Percent]]/100),0) -> 13275 | J42: 1325 | K42: 547 | L42: 200 | M42: 4.39 | N42: 9.04 | O42: 600.01 | P42: West | Q42: Government
A43: CAMP-0067 | B43: Q3-2023 DevOps Accelerator Retargeting | C43: Social Media | D43: Brand Awareness | E43: 45592 | F43: 45677 | G43: 1094418 | H43: 487816 | I43: 8187 | J43: 1785 | K43: 839 | L43: 243 | M43: 1.68 | N43: 133.68 | O43: 4503.78 | P43: East | Q43: Banking
A44: CAMP-0107 | B44: Q4-2025 AI Insights Module Retargeting | C44: LinkedIn | D44: Product Launch | E44: 45585 | F44: 45641 | G44: 519512 | H44: 111222 | I44: 8595 | J44: 551 | K44: 207 | L44: 56 | M44: 7.73 | N44: 60.44 | O44: 9277 | P44: South | Q44: All Industries
A45: CAMP-0109 | B45: Q4-2023 CloudShift Platform Product Launch | C45: LinkedIn | D45: Brand Awareness | E45: 45260 | F45: 45303 | G45: 1125285 | H45: 480535 | I45: 26731 | J45: 6012 | K45: 2554 | L45: 403 | M45: 5.56 | N45: 42.1 | O45: 2792.27 | P45: All Regions | Q45: EdTech
A46: CAMP-0108 | B46: Q4-2025 CloudShift Platform Retargeting | C46: SEO | D46: Product Launch | E46: 45572 | F46: 45592 | G46: 348839 | H46: 69013 | I46: 4567 | J46: 960 | K46: 408 | L46: 61 | M46: 6.62 | N46: 76.38 | O46: 5718.67 | P46: All Regions | Q46: All Industries
A47: CAMP-0145 | B47: Q3-2023 CloudShift Platform Lead Generation | C47: Google Ads | D47: Lead Generation | E47: 45397 | F47: 45434 | G47: 729171 | H47: 43782 | I47: 1128 | J47: 252 | K47: 52 | L47: 8 | M47: 2.58 | N47: 646.43 | O47: 91146.38 | P47: North | Q47: All Industries
A48: CAMP-0070 | B48: Q3-2024 CloudShift Platform Brand Awareness | C48: Google Ads | D48: Lead Generation | E48: 45255 | F48: 45275 | G48: 298026 | H48: 479249 | I48: =ROUND(Table14[[#This Row],[Impressions]]*(Table14[[#This Row],[CTR_Percent]]/100),0) -> 25688 | J48: 6052 | K48: 1602 | L48: 396 | M48: 5.36 | N48: 11.6 | O48: 752.59 | P48: East | Q48: Media
A49: CAMP-0017 | B49: Q1-2023 DataVault Pro Retargeting | C49: Google Ads | D49: Product Launch | E49: 45515 | F49: 45563 | G49: 879818 | H49: 98631 | I49: 3100 | J49: 382 | K49: 98 | L49: 22 | M49: 3.14 | N49: 283.81 | O49: 39991.73 | P49: West | Q49: Unspecified
A50: CAMP-0074 | B50: Q4-2023 DevOps Accelerator Retargeting | C50: Webinar | D50: Lead Generation | E50: 45507 | F50: 45540 | G50: 1464288 | H50: 203793 | I50: 4579 | J50: 415 | K50: 69 | L50: 27 | M50: 2.25 | N50: 319.78 | O50: 54232.89 | P50: East | Q50: Logistics
A51: CAMP-0131 | B51: Q1-2025 DataVault Pro Event Promotion | C51: Trade Show | D51: Retargeting | E51: 45516 | F51: 45585 | G51: 733453 | H51: 239205 | I51: 5167 | J51: 265 | K51: 58 | L51: 9 | M51: 2.16 | N51: 141.95 | O51: 81494.78 | P51: Unspecified | Q51: Telecom
A52: CAMP-0126 | B52: Q3-2025 DataVault Pro Product Launch | C52: Google Ads | D52: Product Launch | E52: 45565 | F52: 45640 | G52: 1066127 | H52: 383129 | I52: 22179 | J52: 5433 | K52: 1427 | L52: 349 | M52: 5.79 | N52: 48.07 | O52: 3054.81 | P52: East | Q52: Banking
...

Sheet Sales_Deals
A1: Deal_ID | B1: Sales_Rep | C1: Client_ID | D1: Product | E1: Lead_Source | F1: Deal_Stage | G1: Deal_Value_INR | H1: Created_Date | I1: Close_Date | J1: Days_to_Close | K1: Discount_Percent | L1: Region | M1: Quarter | N1: Outlier_Flag
A2: DEAL-01440 | B2: Rohit Mehta | C2: CLI-0014 | D2: SecureNet Suite | E2: Referral | F2: Closed Lost | G2: 160271 | H2: 45263 | I2: 45406 | J2: 143 | K2: 3.7 | L2: West | M2: Q4-2023 | N2: Normal
A3: DEAL-02021 | B3: Amit Pillai | C3: CLI-0208 | D3: AI Insights Module | E3: Organic Search | F3: Prospecting | G3: 491510 | H3: 45030 | L3: South | M3: Q2-2023 | N3: Normal
A4: DEAL-00174 | B4: Amit Pillai | C4: CLI-0084 | D4: AI Insights Module | E4: Referral | F4: Proposal Sent | G4: 224184 | H4: 44956 | L4: West | M4: Q1-2023 | N4: Normal
A5: DEAL-02399 | B5: Vikram Patel | C5: CLI-0096 | D5: AnalyticsEdge | E5: Organic Search | F5: Closed Won | G5: 265745 | H5: 45590 | I5: 45650 | J5: 60 | K5: 17.8 | L5: South | M5: Q4-2024 | N5: Normal
A6: DEAL-00243 | B6: Siddharth Joshi | C6: CLI-0071 | D6: DataVault Pro | E6: Email Campaign | F6: Closed Won | G6: 255053 | H6: 45266 | I6: 45429 | J6: 163 | K6: 8.4 | L6: East | M6: Q4-2023 | N6: Normal
A7: DEAL-02410 | B7: Unassigned | C7: CLI-0238 | D7: DataVault Pro | E7: Organic Search | F7: Qualification | G7: 389913 | H7: 45276 | L7: South | M7: Q4-2023 | N7: Normal
A8: DEAL-02158 | B8: Amit Pillai | C8: CLI-0081 | D8: AI Insights Module | E8: Email Campaign | F8: Closed Won | G8: 393048 | H8: 45613 | I8: 45784 | J8: 171 | K8: 1.1 | L8: West | M8: Q4-2024 | N8: Normal
A9: DEAL-01161 | B9: Aditya Pillai | C9: CLI-0236 | D9: AI Insights Module | E9: Google Ads | F9: Closed Won | G9: 295502 | H9: 45696 | I9: 45821 | J9: 125 | K9: 15.8 | L9: East | M9: Q1-2025 | N9: Normal
A10: DEAL-00586 | B10: Meera Reddy | C10: CLI-0128 | D10: CloudShift Platform | E10: Organic Search | F10: Proposal Sent | G10: 172519 | H10: 45371 | K10: 14.2 | L10: South | M10: Q1-2024 | N10: Normal
A11: DEAL-00863 | B11: Aditya Pillai | C11: CLI-0147 | D11: DataVault Pro | E11: LinkedIn Campaign | F11: Closed Won | G11: 146890 | H11: 45356 | I11: 45414 | J11: 58 | K11: 8.5 | L11: West | M11: Q1-2024 | N11: Normal
A12: DEAL-01273 | B12: Ananya Sharma | C12: CLI-0237 | D12: AnalyticsEdge | E12: Webinar | F12: Closed Won | G12: 242460 | H12: 45346 | I12: 45463 | J12: 117 | K12: 23 | L12: East | M12: Q1-2024 | N12: Normal
A13: DEAL-01938 | B13: Siddharth Gupta | C13: CLI-0261 | D13: DataVault Pro | E13: LinkedIn Campaign | F13: Closed Won | G13: 396833 | H13: 45219 | I13: 45236 | J13: 17 | K13: 4.3 | L13: South | M13: Q4-2023 | N13: Normal
A14: DEAL-01122 | B14: Rahul Patel | C14: CLI-0070 | D14: AI Insights Module | E14: Webinar | F14: Closed Won | G14: 207588 | H14: 45335 | I14: 45486 | J14: 151 | K14: 4.3 | L14: East | M14: Q1-2024 | N14: Normal
A15: DEAL-01643 | B15: Riya Das | C15: CLI-0298 | D15: DevOps Accelerator | E15: Referral | F15: Closed Won | G15: 244787 | H15: 45210 | I15: 45327 | J15: 117 | K15: 7.8 | L15: East | M15: Q4-2023 | N15: Normal
A16: DEAL-00234 | B16: Ananya Sharma | C16: CLI-0286 | D16: SecureNet Suite | E16: Trade Show | F16: Closed Won | G16: 223320 | H16: 45623 | I16: 45770 | J16: 147 | K16: 9 | L16: North | M16: Q4-2024 | N16: Normal
A17: DEAL-01783 | B17: Vikram Iyer | C17: CLI-0050 | D17: AI Insights Module | E17: Cold Outreach | F17: Proposal Sent | G17: 341493 | H17: 45142 | L17: West | M17: Q3-2023 | N17: Normal
A18: DEAL-00305 | B18: Neha Pillai | C18: CLI-0035 | D18: AI Insights Module | E18: Google Ads | F18: Closed Lost | G18: 416867 | H18: 45426 | I18: 45541 | J18: 115 | K18: 12.2 | L18: South | M18: Q2-2024 | N18: Normal
A19: DEAL-00351 | B19: Arjun Rao | C19: CLI-0090 | D19: CloudShift Platform | E19: Trade Show | F19: Proposal Sent | G19: 67690 | H19: 45708 | K19: 12.5 | L19: South | M19: Q1-2025 | N19: Normal
A20: DEAL-02148 | B20: Aditya Pillai | C20: CLI-0202 | D20: CloudShift Platform | E20: Email Campaign | F20: Closed Won | G20: 453993 | H20: 45316 | I20: 45466 | J20: 150 | K20: 9.5 | L20: West | M20: Q1-2024 | N20: Normal
A21: DEAL-01377 | B21: Vikram Patel | C21: CLI-0102 | D21: AnalyticsEdge | E21: Trade Show | F21: Proposal Sent | G21: 404058 | H21: 45432 | K21: 5.3 | L21: South | M21: Q2-2024 | N21: Normal
A22: DEAL-01947 | B22: Arjun Rao | C22: CLI-0135 | D22: CloudShift Platform | E22: LinkedIn Campaign | F22: Qualification | G22: 117974 | H22: 44950 | K22: 11.5 | L22: East | M22: Q1-2023 | N22: Normal
A23: DEAL-02354 | B23: Meera Reddy | C23: CLI-0120 | D23: CloudShift Platform | E23: LinkedIn Campaign | F23: Proposal Sent | G23: 111938 | H23: 45725 | L23: South | M23: Q1-2025 | N23: Normal
A24: DEAL-01835 | B24: Rahul Patel | C24: CLI-0070 | D24: AI Insights Module | E24: Cold Outreach | F24: Closed Lost | G24: 133407 | H24: 45046 | I24: 45166 | J24: 120 | K24: 10.9 | L24: North | M24: Q2-2023 | N24: Normal
A25: DEAL-02057 | B25: Deepika Das | C25: CLI-0125 | D25: SecureNet Suite | E25: Unknown | F25: Negotiation | G25: 125962 | H25: 45347 | K25: 12.9 | L25: East | M25: Q1-2024 | N25: Normal
A26: DEAL-00631 | B26: Aditya Pillai | C26: CLI-0222 | D26: AnalyticsEdge | E26: Trade Show | F26: Closed Won | G26: 71017 | H26: 44994 | I26: 45095 | J26: 101 | K26: 3.5 | L26: West | M26: Q1-2023 | N26: Normal
A27: DEAL-02059 | B27: Vikram Iyer | C27: CLI-0191 | D27: AnalyticsEdge | E27: Cold Outreach | F27: Closed Won | G27: 80078 | H27: 45652 | I27: 45722 | J27: 70 | K27: 4.9 | L27: North | M27: Q4-2024 | N27: Normal
A28: DEAL-00946 | B28: Rahul Patel | C28: CLI-0158 | D28: SecureNet Suite | E28: Cold Outreach | F28: Negotiation | G28: 147459 | H28: 45026 | K28: 6.4 | L28: South | M28: Q2-2023 | N28: Normal
A29: DEAL-01560 | B29: Siddharth Gupta | C29: CLI-0219 | D29: AI Insights Module | E29: Webinar | F29: Closed Lost | G29: 59394 | H29: 45278 | I29: 45351 | J29: 73 | K29: 2.1 | L29: East | M29: Q4-2023 | N29: Normal
A30: DEAL-01779 | B30: Neha Pillai | C30: CLI-0266 | D30: CloudShift Platform | E30: LinkedIn Campaign | F30: Prospecting | G30: 490489 | H30: 45699 | L30: North | M30: Q1-2025 | N30: Normal
A31: DEAL-01223 | B31: Ananya Sharma | C31: CLI-0006 | D31: DevOps Accelerator | E31: Trade Show | F31: Proposal Sent | G31: 267116 | H31: 45475 | K31: 3 | L31: South | M31: Q3-2024 | N31: Normal
A32: DEAL-02345 | B32: Riya Das | C32: CLI-0060 | D32: DevOps Accelerator | E32: Trade Show | F32: Closed Lost | G32: 340697 | H32: 45094 | I32: 45174 | J32: 80 | K32: 6.7 | L32: North | M32: Q2-2023 | N32: Normal
A33: DEAL-00816 | B33: Aditya Pillai | C33: CLI-0278 | D33: CloudShift Platform | E33: Referral | F33: Negotiation | G33: 432247 | H33: 45729 | K33: 13.4 | L33: North | M33: Q1-2025 | N33: Normal
A34: DEAL-01909 | B34: Amit Pillai | C34: CLI-0063 | D34: AnalyticsEdge | E34: Email Campaign | F34: Closed Lost | G34: 449838 | H34: 45442 | I34: 45589 | J34: 147 | K34: 6.8 | L34: West | M34: Q2-2024 | N34: Normal
A35: DEAL-00184 | B35: Siddharth Gupta | C35: CLI-0080 | D35: AI Insights Module | E35: LinkedIn Campaign | F35: Negotiation | G35: 325774 | H35: 45335 | L35: West | M35: Q1-2024 | N35: Normal
A36: DEAL-00430 | B36: Siddharth Gupta | C36: CLI-0088 | D36: AnalyticsEdge | E36: Trade Show | F36: Closed Lost | G36: 251845 | H36: 45499 | I36: 45520 | J36: 21 | K36: 6.3 | L36: East | M36: Q3-2024 | N36: Normal
A37: DEAL-01657 | B37: Arjun Rao | C37: CLI-0154 | D37: CloudShift Platform | E37: Cold Outreach | F37: Proposal Sent | G37: 245814 | H37: 45017 | L37: North | M37: Q2-2023 | N37: Normal
A38: DEAL-01118 | B38: Rohit Mehta | C38: CLI-0086 | D38: AI Insights Module | E38: Webinar | F38: Qualification | G38: 128284 | H38: 45083 | K38: 1.5 | L38: South | M38: Q2-2023 | N38: Normal
A39: DEAL-00337 | B39: Meera Reddy | C39: CLI-0286 | D39: SecureNet Suite | E39: Unknown | F39: Proposal Sent | G39: 157092 | H39: 45655 | K39: 6.3 | L39: North | M39: Q4-2024 | N39: Normal
A40: DEAL-01051 | B40: Priya Kumar | C40: CLI-0284 | D40: DevOps Accelerator | E40: Trade Show | F40: Qualification | G40: 387930 | H40: 45587 | K40: 2.8 | L40: West | M40: Q4-2024 | N40: Normal
...

Sheet Support_Tickets
A1: Ticket_ID | B1: Client_ID | C1: Product | D1: Issue_Type | E1: Priority | F1: Created_Date | G1: Resolved_Date | H1: Resolution_Hours | I1: SLA_Target_Hours | J1: SLA_Met | K1: Status | L1: Assigned_Agent | M1: Contact_Channel | N1: Customer_Satisfaction
A2: TKT-01100 | B2: CLI-0182 | C2: DataVault Pro | D2: Access Permission Issue | E2: Low | F2: 45348 | G2: 45350 | H2: 54.6 | I2: 48 | J2: No | K2: Resolved | L2: Unassigned | M2: Email | N2: 4
A3: TKT-02536 | B3: CLI-0020 | C3: AI Insights Module | D3: Feature Request | E3: Medium | F3: 45520 | G3: 45521 | H3: 25.9 | I3: 24 | J3: No | K3: Resolved | L3: Ananya Joshi | M3: Chat | N3: 1
A4: TKT-00220 | B4: CLI-0156 | C4: AI Insights Module | D4: Feature Request | E4: Medium | F4: 45230 | G4: 45230 | H4: 10.1 | I4: 24 | J4: Yes | K4: Resolved | L4: Rahul Das | M4: Phone | N4: 3
A5: TKT-02139 | B5: CLI-0222 | C5: DevOps Accelerator | D5: Login Issue | E5: Medium | F5: 45149 | I5: 24 | J5: Yes | K5: Escalated | L5: Pooja Iyer | M5: Email
A6: TKT-01110 | B6: CLI-0247 | C6: CloudShift Platform | D6: Feature Request | E6: Critical | F6: 45394 | I6: 4 | J6: Yes | K6: In Progress | L6: Divya Reddy | M6: Chat
A7: TKT-03054 | B7: CLI-0169 | C7: CloudShift Platform | D7: Onboarding Support | E7: Critical | F7: 45319 | G7: 45319 | H7: 8.4 | I7: 4 | J7: No | K7: Resolved | L7: Pooja Patel | M7: Portal | N7: 3
A8: TKT-00333 | B8: CLI-0074 | C8: DevOps Accelerator | D8: Security Alert | E8: Low | F8: 45700 | G8: 45702 | H8: 54.5 | I8: 48 | J8: No | K8: Resolved | L8: Pooja Gupta | M8: Chat | N8: 3
A9: TKT-01472 | B9: CLI-0288 | C9: SecureNet Suite | D9: Security Alert | E9: Medium | F9: 45570 | I9: 24 | J9: No | K9: Escalated | L9: Manish Nair | M9: Phone
A10: TKT-01841 | B10: CLI-0206 | C10: AI Insights Module | D10: API Integration Failure | E10: Medium | F10: 45103 | G10: 45103 | H10: 2.6 | I10: 24 | J10: Yes | K10: Resolved | L10: Priya Nair | M10: Portal | N10: 3
A11: TKT-00445 | B11: CLI-0230 | C11: DevOps Accelerator | D11: Dashboard Bug | E11: High | F11: 45024 | I11: 8 | J11: Yes | K11: Open | L11: Divya Reddy | M11: Portal
A12: TKT-03379 | B12: CLI-0033 | C12: AnalyticsEdge | D12: Billing Query | E12: Low | F12: 44932 | I12: 48 | J12: No | K12: Open | L12: Priya Nair | M12: Portal
A13: TKT-01818 | B13: CLI-0029 | C13: DataVault Pro | D13: API Integration Failure | E13: Medium | F13: 45250 | G13: 45252 | H13: 50.4 | I13: 24 | J13: Unknown | K13: Resolved | L13: Manish Nair | M13: Portal | N13: 3
A14: TKT-00367 | B14: CLI-0184 | C14: CloudShift Platform | D14: Report Inaccuracy | E14: High | F14: 45029 | I14: 8 | J14: No | K14: Open | L14: Neha Gupta | M14: Portal
A15: TKT-03060 | B15: CLI-0057 | C15: DevOps Accelerator | D15: Performance Lag | E15: Medium | F15: 45490 | G15: 45492 | H15: 54.8 | I15: 24 | J15: No | K15: Resolved | L15: Deepika Mishra | M15: Email | N15: 4
A16: TKT-03487 | B16: CLI-0205 | C16: CloudShift Platform | D16: Data Sync Error | E16: Medium | F16: 44983 | I16: 24 | J16: No | K16: Escalated | L16: Manish Nair | M16: Email
A17: TKT-03741 | B17: CLI-0183 | C17: SecureNet Suite | D17: Onboarding Support | E17: Medium | F17: 45046 | I17: 24 | J17: Yes | K17: Open | L17: Manish Nair | M17: Email
A18: TKT-01257 | B18: CLI-0068 | C18: AnalyticsEdge | D18: Feature Request | E18: High | F18: 45076 | G18: 45076 | H18: 14 | I18: 8 | J18: No | K18: Resolved | L18: Nikhil Mehta | M18: Chat | N18: 5
A19: TKT-01790 | B19: CLI-0205 | C19: AI Insights Module | D19: Server Downtime | E19: Medium | F19: 45328 | I19: 24 | J19: Unknown | K19: Open | L19: Manish Nair | M19: Portal
A20: TKT-02799 | B20: CLI-0093 | C20: CloudShift Platform | D20: Access Permission Issue | E20: Low | F20: 44999 | I20: 48 | J20: No | K20: Open | L20: Kavya Iyer | M20: Email
A21: TKT-00635 | B21: CLI-0099 | C21: AnalyticsEdge | D21: Onboarding Support | E21: Medium | F21: 45284 | I21: 24 | J21: Yes | K21: Escalated | L21: Kavya Iyer | M21: Chat
A22: TKT-01805 | B22: CLI-0161 | C22: DataVault Pro | D22: Report Inaccuracy | E22: Low | F22: 45729 | G22: 45729 | H22: 11.8 | I22: 48 | J22: Yes | K22: Resolved | L22: Neha Gupta | M22: Chat | N22: 3
A23: TKT-03253 | B23: CLI-0121 | C23: SecureNet Suite | D23: Server Downtime | E23: Medium | F23: 45496 | G23: 45497 | H23: 39.3 | I23: 24 | J23: No | K23: Resolved | L23: Pooja Gupta | M23: Email | N23: 2
A24: TKT-00709 | B24: CLI-0017 | C24: AI Insights Module | D24: Data Sync Error | E24: Critical | F24: 45539 | I24: 4 | J24: No | K24: Open | L24: Unassigned | M24: Email
A25: TKT-00343 | B25: CLI-0127 | C25: CloudShift Platform | D25: Access Permission Issue | E25: Medium | F25: 45722 | G25: 45723 | H25: 31.4 | I25: 24 | J25: No | K25: Resolved | L25: Neha Gupta | M25: Chat | N25: 4
A26: TKT-03567 | B26: CLI-0107 | C26: AI Insights Module | D26: Server Downtime | E26: Critical | F26: 45176 | G26: 45176 | H26: 8.7 | I26: 4 | J26: No | K26: Resolved | L26: Unassigned | M26: Email | N26: 4
A27: TKT-02295 | B27: CLI-0158 | C27: SecureNet Suite | D27: Login Issue | E27: Low | F27: 45431 | I27: 48 | J27: Yes | K27: Open | L27: Priya Nair | M27: Portal
A28: TKT-02678 | B28: CLI-0279 | C28: AnalyticsEdge | D28: Data Sync Error | E28: Low | F28: 45541 | G28: 45543 | H28: 67.1 | I28: 48 | J28: No | K28: Resolved | L28: Siddharth Reddy | M28: Portal | N28: 4
A29: TKT-03086 | B29: CLI-0298 | C29: DataVault Pro | D29: Onboarding Support | E29: Low | F29: 45314 | G29: 45315 | H29: 32.4 | I29: 48 | J29: Yes | K29: Resolved | L29: Pooja Gupta | M29: Phone | N29: 4
A30: TKT-00950 | B30: CLI-0014 | C30: AI Insights Module | D30: Login Issue | E30: Low | F30: 45597 | G30: 45601 | H30: 105.1 | I30: 48 | J30: No | K30: Resolved | L30: Pooja Patel | M30: Phone | N30: 4
A31: TKT-02137 | B31: CLI-0088 | C31: CloudShift Platform | D31: Login Issue | E31: Low | F31: 45571 | I31: 48 | J31: Yes | K31: In Progress | L31: Kavya Iyer | M31: Phone
A32: TKT-03836 | B32: CLI-0080 | C32: CloudShift Platform | D32: Performance Lag | E32: Medium | F32: 45016 | I32: 24 | J32: Yes | K32: Escalated | L32: Kavya Iyer | M32: Portal
A33: TKT-03334 | B33: CLI-0165 | C33: AnalyticsEdge | D33: Login Issue | E33: Critical | F33: 45264 | G33: 45264 | H33: 2.5 | I33: 4 | J33: Yes | K33: Resolved | L33: Rahul Das | M33: Portal
A34: TKT-03902 | B34: CLI-0278 | C34: DevOps Accelerator | D34: Onboarding Support | E34: Low | F34: 45375 | G34: 45376 | H34: 40.3 | I34: 48 | J34: Yes | K34: Resolved | L34: Rahul Das | M34: Phone | N34: 5
A35: TKT-02387 | B35: CLI-0265 | C35: DevOps Accelerator | D35: Server Downtime | E35: Critical | F35: 45646 | G35: 45646 | H35: 7.5 | I35: 4 | J35: No | K35: Resolved | L35: Karan Gupta | M35: Portal | N35: 4
A36: TKT-03282 | B36: CLI-0089 | C36: AI Insights Module | D36: Onboarding Support | E36: Medium | F36: 45332 | I36: 24 | J36: Yes | K36: In Progress | L36: Manish Nair | M36: Email
A37: TKT-03494 | B37: CLI-0134 | C37: DevOps Accelerator | D37: Server Downtime | E37: Medium | F37: 45196 | I37: 24 | J37: No | K37: Escalated | L37: Arjun Mishra | M37: Phone
A38: TKT-02380 | B38: CLI-0131 | C38: AI Insights Module | D38: Performance Lag | E38: Medium | F38: 45330 | I38: 24 | J38: No | K38: In Progress | L38: Priya Patel | M38: Phone
A39: TKT-03553 | B39: CLI-0150 | C39: DevOps Accelerator | D39: Access Permission Issue | E39: Low | F39: 45079 | I39: 48 | J39: No | K39: Escalated | L39: Rahul Das | M39: Phone
A40: TKT-03523 | B40: CLI-0104 | C40: DevOps Accelerator | D40: Report Inaccuracy | E40: Medium | F40: 45530 | G40: 45531 | H40: 24.6 | I40: 24 | J40: No | K40: Resolved | L40: Neha Gupta | M40: Email | N40: 3
...

Sheet Q34_Win_Rate
A1: H1 - Digital vs Offline Lead Source: Win Rate(Chi-Square Test)
A2: H0: Win rate is independent of channel type (digital vs offline).
A3: H1: Win rate differs by channel type.
A5: Digital = Google Ads, LinkedIn Campaign, Email Campaign.
A6: Offline = Referral, Trade Show, Cold Outreach.
A7: (Organic Search, Webinar, Unknown excluded — not named in either group by the brief.)
A9: Observed Contigency Table
A10: Channel | B10: Closed Won | C10: Closed Lost | D10: Total
A11: Digital | B11: =COUNTIFS(Sales_Deals!$E$2:$E$2501,"Google Ads",Sales_Deals!$F$2:$F$2501,"Closed Won")+COUNTIFS(Sales_Deals!$E$2:$E$2501,"LinkedIn Campaign",Sales_Deals!$F$2:$F$2501,"Closed Won")+COUNTIFS(Sales_Deals!$E$2:$E$2501,"Email Campaign",Sales_Deals!$F$2:$F$2501,"Closed Won") -> 224 | C11: =COUNTIFS(Sales_Deals!$E$2:$E$2501,"Google Ads",Sales_Deals!$F$2:$F$2501,"Closed Lost")+COUNTIFS(Sales_Deals!$E$2:$E$2501,"LinkedIn Campaign",Sales_Deals!$F$2:$F$2501,"Closed Lost")+COUNTIFS(Sales_Deals!$E$2:$E$2501,"Email Campaign",Sales_Deals!$F$2:$F$2501,"Closed Lost") -> 129 | D11: =B11+C11 -> 353
A12: Offline | B12: =COUNTIFS(Sales_Deals!$E$2:$E$2501,"Referral",Sales_Deals!$F$2:$F$2501,"Closed Won")+COUNTIFS(Sales_Deals!$E$2:$E$2501,"Trade Show",Sales_Deals!$F$2:$F$2501,"Closed Won")+COUNTIFS(Sales_Deals!$E$2:$E$2501,"Cold Outreach",Sales_Deals!$F$2:$F$2501,"Closed Won") -> 245 | C12: =COUNTIFS(Sales_Deals!$E$2:$E$2501,"Referral",Sales_Deals!$F$2:$F$2501,"Closed Lost")+COUNTIFS(Sales_Deals!$E$2:$E$2501,"Trade Show",Sales_Deals!$F$2:$F$2501,"Closed Lost")+COUNTIFS(Sales_Deals!$E$2:$E$2501,"Cold Outreach",Sales_Deals!$F$2:$F$2501,"Closed Lost") -> 137 | D12: =B12+C12 -> 382
A13: Total | B13: =B11+B12 -> 469 | C13: =C11+C12 -> 266 | D13: =D11+D12 -> 735
A15: Expected Counts (if independent)
A16: Channel | B16: Closed Won | C16: Closed lost
A17: Digital | B17: =$D11*B$13/$D$13 -> 225.24762 | C17: =$D11*C$13/$D$13 -> 127.75238
A18: Offline | B18: =$D12*B$13/$D$13 -> 243.75238 | C18: =$D12*C$13/$D$13 -> 138.24762
A20: Test Results
A21: Chi-Square Statistic | B21: =SUM((B11-B17)^2/B17,(C11-C17)^2/C17,(B12-B18)^2/B18,(C12-C18)^2/C18) -> 0.036739519
A22: Degrees of Freedom | B22: =(COUNTA(A11:A12)-1)*(COUNTA(Table6[[#Headers],[Closed Won]:[Closed Lost]])-1) -> 1
A23: p-Value | B23: =_xlfn.CHISQ.DIST.RT(B21,B22) -> 0.84799635
A24: Digital win rate | B24: =B11/D11 -> 0.63456091
A25: Offline will rate | B25: =B12/D12 -> 0.64136126
A27: Conclusion (Alpha=0.05) | B27: =IF(B23<0.05,"Reject H0 - Significant difference in win rates","Fail to reject H0 - No significant difference in win rates") -> Fail to reject H0 - No significant difference in win rates

Sheet Q35_Closure_Time
A1: H2 — Deal Closure Time:
A2: Recent 6 Months vs Previous 6 Months (T-Test)
A4: H0: Mean days-to-close is the same in both periods.
A5: H1: Mean days-to-close has increased in the recent period.
A7: Periods defined by Close_Date, relative to the dataset’s latest full quarter-end (2025-03-31). Recent = 2024-10-01 to 2025-03-31. Previous = 2024-04-01 to 2024-09-30.
A9: Helper columns (Days_to_Close pulled into each period; blank if the deal falls outside it)
A10: Row No. | B10: Recent_6 _Months | C10: Previous_6_Months | I10: Periods by Close_Date: Recent = 2024-10-01 to 2025-03-31. Previous = 2024-04-01 to 2024-09-30.
A11: 1 | B11: =IF(Sales_Deals!I2<>"",IF(AND(Sales_Deals!I2>DATE(2024,9,30),Sales_Deals!I2<=DATE(2025,3,31)),Sales_Deals!J2,""),"") | C11: =IF(Sales_Deals!I2<>"",IF(AND(Sales_Deals!I2>DATE(2024,3,31),Sales_Deals!I2<=DATE(2024,9,30)),Sales_Deals!J2,""),"") -> 143 | I11: Months | J11: n | K11: Mean | L11: Std Dev
A12: 2 | B12: =IF(Sales_Deals!I3<>"",IF(AND(Sales_Deals!I3>DATE(2024,9,30),Sales_Deals!I3<=DATE(2025,3,31)),Sales_Deals!J3,""),"") | C12: =IF(Sales_Deals!I3<>"",IF(AND(Sales_Deals!I3>DATE(2024,3,31),Sales_Deals!I3<=DATE(2024,9,30)),Sales_Deals!J3,""),"") | I12: Recent 6 Months | J12: =COUNT(B11:B2510) -> 205 | K12: =AVERAGE(B11:B2510) -> 100.57561 | L12: =STDEV(B11:B2510) -> 50.325805
A13: 3 | B13: =IF(Sales_Deals!I4<>"",IF(AND(Sales_Deals!I4>DATE(2024,9,30),Sales_Deals!I4<=DATE(2025,3,31)),Sales_Deals!J4,""),"") | C13: =IF(Sales_Deals!I4<>"",IF(AND(Sales_Deals!I4>DATE(2024,3,31),Sales_Deals!I4<=DATE(2024,9,30)),Sales_Deals!J4,""),"") | I13: Previous 6 Months | J13: =COUNT(C11:C2510) -> 221 | K13: =AVERAGE(C11:C2510) -> 97.289593 | L13: =STDEV(C11:C2510) -> 50.230083
A14: 4 | B14: =IF(Sales_Deals!I5<>"",IF(AND(Sales_Deals!I5>DATE(2024,9,30),Sales_Deals!I5<=DATE(2025,3,31)),Sales_Deals!J5,""),"") -> 60 | C14: =IF(Sales_Deals!I5<>"",IF(AND(Sales_Deals!I5>DATE(2024,3,31),Sales_Deals!I5<=DATE(2024,9,30)),Sales_Deals!J5,""),"")
A15: 5 | B15: =IF(Sales_Deals!I6<>"",IF(AND(Sales_Deals!I6>DATE(2024,9,30),Sales_Deals!I6<=DATE(2025,3,31)),Sales_Deals!J6,""),"") | C15: =IF(Sales_Deals!I6<>"",IF(AND(Sales_Deals!I6>DATE(2024,3,31),Sales_Deals!I6<=DATE(2024,9,30)),Sales_Deals!J6,""),"") -> 163
A16: 6 | B16: =IF(Sales_Deals!I7<>"",IF(AND(Sales_Deals!I7>DATE(2024,9,30),Sales_Deals!I7<=DATE(2025,3,31)),Sales_Deals!J7,""),"") | C16: =IF(Sales_Deals!I7<>"",IF(AND(Sales_Deals!I7>DATE(2024,3,31),Sales_Deals!I7<=DATE(2024,9,30)),Sales_Deals!J7,""),"") | I16: Test Results
A17: 7 | B17: =IF(Sales_Deals!I8<>"",IF(AND(Sales_Deals!I8>DATE(2024,9,30),Sales_Deals!I8<=DATE(2025,3,31)),Sales_Deals!J8,""),"") | C17: =IF(Sales_Deals!I8<>"",IF(AND(Sales_Deals!I8>DATE(2024,3,31),Sales_Deals!I8<=DATE(2024,9,30)),Sales_Deals!J8,""),"") | I17: Mean difference (Recent - Previous) | J17: =K12-K13 -> 3.286017
A18: 8 | B18: =IF(Sales_Deals!I9<>"",IF(AND(Sales_Deals!I9>DATE(2024,9,30),Sales_Deals!I9<=DATE(2025,3,31)),Sales_Deals!J9,""),"") | C18: =IF(Sales_Deals!I9<>"",IF(AND(Sales_Deals!I9>DATE(2024,3,31),Sales_Deals!I9<=DATE(2024,9,30)),Sales_Deals!J9,""),"") | I18: p-value (two-tailed) | J18: =TTEST(B11:B2510,C11:C2510,2,3) -> 0.50069562
A19: 9 | B19: =IF(Sales_Deals!I10<>"",IF(AND(Sales_Deals!I10>DATE(2024,9,30),Sales_Deals!I10<=DATE(2025,3,31)),Sales_Deals!J10,""),"") | C19: =IF(Sales_Deals!I10<>"",IF(AND(Sales_Deals!I10>DATE(2024,3,31),Sales_Deals!I10<=DATE(2024,9,30)),Sales_Deals!J10,""),"")
A20: 10 | B20: =IF(Sales_Deals!I11<>"",IF(AND(Sales_Deals!I11>DATE(2024,9,30),Sales_Deals!I11<=DATE(2025,3,31)),Sales_Deals!J11,""),"") | C20: =IF(Sales_Deals!I11<>"",IF(AND(Sales_Deals!I11>DATE(2024,3,31),Sales_Deals!I11<=DATE(2024,9,30)),Sales_Deals!J11,""),"") -> 58 | I20: Conclusion | J20: =IF(J18<0.05,"Reject H0 - closure time has changed","Fail to reject H0 - no significant change") -> Fail to reject H0 - no significant change
A21: 11 | B21: =IF(Sales_Deals!I12<>"",IF(AND(Sales_Deals!I12>DATE(2024,9,30),Sales_Deals!I12<=DATE(2025,3,31)),Sales_Deals!J12,""),"") | C21: =IF(Sales_Deals!I12<>"",IF(AND(Sales_Deals!I12>DATE(2024,3,31),Sales_Deals!I12<=DATE(2024,9,30)),Sales_Deals!J12,""),"") -> 117
A22: 12 | B22: =IF(Sales_Deals!I13<>"",IF(AND(Sales_Deals!I13>DATE(2024,9,30),Sales_Deals!I13<=DATE(2025,3,31)),Sales_Deals!J13,""),"") | C22: =IF(Sales_Deals!I13<>"",IF(AND(Sales_Deals!I13>DATE(2024,3,31),Sales_Deals!I13<=DATE(2024,9,30)),Sales_Deals!J13,""),"")
A23: 13 | B23: =IF(Sales_Deals!I14<>"",IF(AND(Sales_Deals!I14>DATE(2024,9,30),Sales_Deals!I14<=DATE(2025,3,31)),Sales_Deals!J14,""),"") | C23: =IF(Sales_Deals!I14<>"",IF(AND(Sales_Deals!I14>DATE(2024,3,31),Sales_Deals!I14<=DATE(2024,9,30)),Sales_Deals!J14,""),"") -> 151
A24: 14 | B24: =IF(Sales_Deals!I15<>"",IF(AND(Sales_Deals!I15>DATE(2024,9,30),Sales_Deals!I15<=DATE(2025,3,31)),Sales_Deals!J15,""),"") | C24: =IF(Sales_Deals!I15<>"",IF(AND(Sales_Deals!I15>DATE(2024,3,31),Sales_Deals!I15<=DATE(2024,9,30)),Sales_Deals!J15,""),"")
A25: 15 | B25: =IF(Sales_Deals!I16<>"",IF(AND(Sales_Deals!I16>DATE(2024,9,30),Sales_Deals!I16<=DATE(2025,3,31)),Sales_Deals!J16,""),"") | C25: =IF(Sales_Deals!I16<>"",IF(AND(Sales_Deals!I16>DATE(2024,3,31),Sales_Deals!I16<=DATE(2024,9,30)),Sales_Deals!J16,""),"")
A26: 16 | B26: =IF(Sales_Deals!I17<>"",IF(AND(Sales_Deals!I17>DATE(2024,9,30),Sales_Deals!I17<=DATE(2025,3,31)),Sales_Deals!J17,""),"") | C26: =IF(Sales_Deals!I17<>"",IF(AND(Sales_Deals!I17>DATE(2024,3,31),Sales_Deals!I17<=DATE(2024,9,30)),Sales_Deals!J17,""),"")
A27: 17 | B27: =IF(Sales_Deals!I18<>"",IF(AND(Sales_Deals!I18>DATE(2024,9,30),Sales_Deals!I18<=DATE(2025,3,31)),Sales_Deals!J18,""),"") | C27: =IF(Sales_Deals!I18<>"",IF(AND(Sales_Deals!I18>DATE(2024,3,31),Sales_Deals!I18<=DATE(2024,9,30)),Sales_Deals!J18,""),"") -> 115
A28: 18 | B28: =IF(Sales_Deals!I19<>"",IF(AND(Sales_Deals!I19>DATE(2024,9,30),Sales_Deals!I19<=DATE(2025,3,31)),Sales_Deals!J19,""),"") | C28: =IF(Sales_Deals!I19<>"",IF(AND(Sales_Deals!I19>DATE(2024,3,31),Sales_Deals!I19<=DATE(2024,9,30)),Sales_Deals!J19,""),"")
A29: 19 | B29: =IF(Sales_Deals!I20<>"",IF(AND(Sales_Deals!I20>DATE(2024,9,30),Sales_Deals!I20<=DATE(2025,3,31)),Sales_Deals!J20,""),"") | C29: =IF(Sales_Deals!I20<>"",IF(AND(Sales_Deals!I20>DATE(2024,3,31),Sales_Deals!I20<=DATE(2024,9,30)),Sales_Deals!J20,""),"") -> 150
A30: 20 | B30: =IF(Sales_Deals!I21<>"",IF(AND(Sales_Deals!I21>DATE(2024,9,30),Sales_Deals!I21<=DATE(2025,3,31)),Sales_Deals!J21,""),"") | C30: =IF(Sales_Deals!I21<>"",IF(AND(Sales_Deals!I21>DATE(2024,3,31),Sales_Deals!I21<=DATE(2024,9,30)),Sales_Deals!J21,""),"")
A31: 21 | B31: =IF(Sales_Deals!I22<>"",IF(AND(Sales_Deals!I22>DATE(2024,9,30),Sales_Deals!I22<=DATE(2025,3,31)),Sales_Deals!J22,""),"") | C31: =IF(Sales_Deals!I22<>"",IF(AND(Sales_Deals!I22>DATE(2024,3,31),Sales_Deals!I22<=DATE(2024,9,30)),Sales_Deals!J22,""),"")
A32: 22 | B32: =IF(Sales_Deals!I23<>"",IF(AND(Sales_Deals!I23>DATE(2024,9,30),Sales_Deals!I23<=DATE(2025,3,31)),Sales_Deals!J23,""),"") | C32: =IF(Sales_Deals!I23<>"",IF(AND(Sales_Deals!I23>DATE(2024,3,31),Sales_Deals!I23<=DATE(2024,9,30)),Sales_Deals!J23,""),"")
... A2510: 2500 | B2510: =IF(Sales_Deals!I2501<>"",IF(AND(Sales_Deals!I2501>DATE(2024,9,30),Sales_Deals!I2501<=DATE(2025,3,31)),Sales_Deals!J2501,""),"") | C2510: =IF(Sales_Deals!I2501<>"",IF(AND(Sales_Deals!I2501>DATE(2024,3,31),Sales_Deals!I2501<=DATE(2024,9,30)),Sales_Deals!J2501,""),"")

Sheet Q36_Correlation
A1: H3 — Client Satisfaction Score vs. SLA Breach Count (Correlation)
A3: H0: No linear relationship between satisfaction score and SLA breach count.
A4: H1: A significant correlation exists.
A6: Aggregated to one row per client. Breach Count = number of that client’s support tickets where SLA_Met = "No".
A8: Client_ID | B8: Satisfaction_Score | C8: SLA_Breach_Count | G8: Test Results
A9: =Clients!A2 -> CLI-0113 | B9: =IF(Clients!H2="","",Clients!H2) -> 3.2 | C9: =COUNTIFS(Support_Tickets!$B$2:$B$4001,A9,Support_Tickets!$J$2:$J$4001,"No") -> 10 | G9: n (Clients with a satisfaction score) | H9: =COUNT(B9:B308) -> 286
A10: =Clients!A3 -> CLI-0047 | B10: =IF(Clients!H3="","",Clients!H3) -> 3.1 | C10: =COUNTIFS(Support_Tickets!$B$2:$B$4001,A10,Support_Tickets!$J$2:$J$4001,"No") -> 10 | G10: Pearson r | H10: =PEARSON(B9:B308,C9:C308) -> 0.046973468
A11: =Clients!A4 -> CLI-0083 | B11: =IF(Clients!H4="","",Clients!H4) -> 4.4 | C11: =COUNTIFS(Support_Tickets!$B$2:$B$4001,A11,Support_Tickets!$J$2:$J$4001,"No") -> 4 | G11: t-statistic | H11: =H10*SQRT(H9-2)/SQRT(1-H10^2) -> 0.79248575
A12: =Clients!A5 -> CLI-0111 | B12: =IF(Clients!H5="","",Clients!H5) -> 4.9 | C12: =COUNTIFS(Support_Tickets!$B$2:$B$4001,A12,Support_Tickets!$J$2:$J$4001,"No") -> 9 | G12: Degrees of freedom | H12: =H9-2 -> 284
A13: =Clients!A6 -> CLI-0199 | B13: =IF(Clients!H6="","",Clients!H6) -> 4.3 | C13: =COUNTIFS(Support_Tickets!$B$2:$B$4001,A13,Support_Tickets!$J$2:$J$4001,"No") -> 6 | G13: p-value | H13: =TDIST(ABS(H11),H12,2) -> 0.42873898
A14: =Clients!A7 -> CLI-0213 | B14: =IF(Clients!H7="","",Clients!H7) -> 3.8 | C14: =COUNTIFS(Support_Tickets!$B$2:$B$4001,A14,Support_Tickets!$J$2:$J$4001,"No") -> 8
