Workbook

Sheet Summary
A1: Task/Case Study 2
A2: Cleaning the Lens - Data Preparation and Departmental Analysis
A3: NovaByte Solutions | Sales & Finance
A5: Part A - Data Cleaning Summary
A6: 1 | B6: Dates standardized: Sales_Deals.Created_Date mixed 91 text-formatted dates (MM/DD/YYYY) with proper datetime values; all dates across both files now display as YYYY-MM-DD.
A7: 2 | B7: Duplicates removed: 40 exact duplicate rows in Sales_Deals (2,540 → 2,500) and 25 in Finance_Expenses (1,025 → 1,000).
A8: 3 | B8: Missing values - Sales_Deals: Sales_Rep and Lead_Source blanks filled with placeholder values ("Unassigned"/"Unknown"); Discount_Percent left blank where missing rather than guessed. Close_Date/Days_to_Close are blank on open deals - expected, not an error.
A9: 4 | B9: Missing values - Finance_Expenses: Department and Category blanks filled with placeholder values; Budget_Allocated_INR (and therefore Variance) left blank where the source data had no budget figure to work from.
A10: 5 | B10: Text fields (casing, extra spaces, blank names): checked across Sales_Rep, Product, Lead_Source, Deal_Stage, Region, Department, Category, and Vendor - no casing or whitespace inconsistencies were found in this data pull. All categorical values are already clean and consistently formatted.
A11: 6 | B11: Outlier deal values: 40 deals flagged above the mean + 3 standard deviation threshold - kept in the data, not removed, since large deals can be legitimate.
A12: 7 | B12: Negative Finance amounts: 40 rows with negative Amount_INR kept as is - these are credit/refund transactions, not data errors.
A14: Part B - Sales Analysis: Key Findings
A15: 1 | B15: Revenue is trending down: Closed Won revenue fell from ₹2.33 crore in Q1-2023 to ₹1.55 crore in Q1-2025 - a decline of roughly a third over nine quarters, not a single-quarter dip. This directly supports the case brief's premise of a revenue slowdown.
A16: 2 | B16: Win rate is healthy and fairly consistent: in the 55 - 71% range across sales reps, and a narrower 61- 67% range across regions - no single rep or region stands out as a structural problem, though the lower performers may be worth a coaching conversation.
A17: 3 | B17: Days-to-close varies more by lead source than by product: Cold Outreach and Webinar-sourced deals close fastest; Trade Show and unrecorded ("Unknown") lead sources take noticeably longer.
A19: Part C - Finance Analysis: Key Findings
A20: 1 | B20: At the department level, every department is under its cumulative allocated budget for the period - none show a positive (over-budget) variance in aggregate.
A21: 2 | B21: Top vendors by total spend: Wipro, Zoom, TCS, AWS, and Google Cloud lead the list - cloud infrastructure and consulting/collaboration tools account for the largest share of vendor spend.
A22: 3 | B22: 181 expense records exceeding ₹200,000 are currently sitting in Pending or Rejected status - a meaningful amount of spend in unresolved approval limbo, worth flagging to Finance leadership for follow-up.
A24: Where to Find Each Deliverable Item
A25: 1 | B25: Raw data: Raw_Sales_Deals, Raw_Finance_Expenses
A26: 2 | B26: Cleaned data: Cleaned_Sales_Deals, Cleaned_Finance_Expenses
A27: 3 | B27: Pivot tables, win rate, days-to-close, and revenue chart: Sales Analysis
A28: 4 | B28: Expense pivot, budget variance, top vendors, and flagged expenses: Finance Analysis

Sheet Raw_Sales_Deals
A1: Deal_ID | B1: Sales_Rep | C1: Client_ID | D1: Product | E1: Lead_Source | F1: Deal_Stage | G1: Deal_Value_INR | H1: Created_Date | I1: Close_Date | J1: Days_to_Close | K1: Discount_Percent | L1: Region | M1: Quarter
A2: DEAL-01440 | B2: Rohit Mehta | C2: CLI-0014 | D2: SecureNet Suite | E2: Referral | F2: Closed Lost | G2: 160271 | H2: 2023-12-03 | I2: 45406 | J2: 143 | K2: 3.7 | L2: West | M2: Q4-2023
A3: DEAL-02021 | B3: Amit Pillai | C3: CLI-0208 | D3: AI Insights Module | E3: Organic Search | F3: Prospecting | G3: 491510 | H3: 2023-04-14 | L3: South | M3: Q2-2023
A4: DEAL-00174 | B4: Amit Pillai | C4: CLI-0084 | D4: AI Insights Module | E4: Referral | F4: Proposal Sent | G4: 224184 | H4: 2023-01-30 | L4: West | M4: Q1-2023
A5: DEAL-02399 | B5: Vikram Patel | C5: CLI-0096 | D5: AnalyticsEdge | E5: Organic Search | F5: Closed Won | G5: 265745 | H5: 2024-10-25 | I5: 45650 | J5: 60 | K5: 17.8 | L5: South | M5: Q4-2024
A6: DEAL-00243 | B6: Siddharth Joshi | C6: CLI-0071 | D6: DataVault Pro | E6: Email Campaign | F6: Closed Won | G6: 255053 | H6: 2023-12-06 | I6: 45429 | J6: 163 | K6: 8.4 | L6: East | M6: Q4-2023
A7: DEAL-02410 | C7: CLI-0238 | D7: DataVault Pro | E7: Organic Search | F7: Qualification | G7: 389913 | H7: 2023-12-16 | L7: South | M7: Q4-2023
A8: DEAL-02158 | B8: Amit Pillai | C8: CLI-0081 | D8: AI Insights Module | E8: Email Campaign | F8: Closed Won | G8: 393048 | H8: 2024-11-17 | I8: 45784 | J8: 171 | K8: 1.1 | L8: West | M8: Q4-2024
A9: DEAL-01161 | B9: Aditya Pillai | C9: CLI-0236 | D9: AI Insights Module | E9: Google Ads | F9: Closed Won | G9: 295502 | H9: 2025-02-08 | I9: 45821 | J9: 125 | K9: 15.8 | L9: East | M9: Q1-2025
A10: DEAL-00586 | B10: Meera Reddy | C10: CLI-0128 | D10: CloudShift Platform | E10: Organic Search | F10: Proposal Sent | G10: 172519 | H10: 2024-03-20 | K10: 14.2 | L10: South | M10: Q1-2024
A11: DEAL-00863 | B11: Aditya Pillai | C11: CLI-0147 | D11: DataVault Pro | E11: LinkedIn Campaign | F11: Closed Won | G11: 146890 | H11: 2024-03-05 | I11: 45414 | J11: 58 | K11: 8.5 | L11: West | M11: Q1-2024
A12: DEAL-01273 | B12: Ananya Sharma | C12: CLI-0237 | D12: AnalyticsEdge | E12: Webinar | F12: Closed Won | G12: 242460 | H12: 2024-02-24 | I12: 45463 | J12: 117 | K12: 23 | L12: East | M12: Q1-2024
A13: DEAL-01938 | B13: Siddharth Gupta | C13: CLI-0261 | D13: DataVault Pro | E13: LinkedIn Campaign | F13: Closed Won | G13: 396833 | H13: 2023-10-20 | I13: 45236 | J13: 17 | K13: 4.3 | L13: South | M13: Q4-2023
A14: DEAL-01122 | B14: Rahul Patel | C14: CLI-0070 | D14: AI Insights Module | E14: Webinar | F14: Closed Won | G14: 207588 | H14: 2024-02-13 | I14: 45486 | J14: 151 | K14: 4.3 | L14: East | M14: Q1-2024
A15: DEAL-01643 | B15: Riya Das | C15: CLI-0298 | D15: DevOps Accelerator | E15: Referral | F15: Closed Won | G15: 244787 | H15: 2023-10-11 | I15: 45327 | J15: 117 | K15: 7.8 | L15: East | M15: Q4-2023
A16: DEAL-00234 | B16: Ananya Sharma | C16: CLI-0286 | D16: SecureNet Suite | E16: Trade Show | F16: Closed Won | G16: 223320 | H16: 2024-11-27 | I16: 45770 | J16: 147 | K16: 9 | L16: North | M16: Q4-2024
A17: DEAL-01783 | B17: Vikram Iyer | C17: CLI-0050 | D17: AI Insights Module | E17: Cold Outreach | F17: Proposal Sent | G17: 341493 | H17: 2023-08-04 | L17: West | M17: Q3-2023
A18: DEAL-00305 | B18: Neha Pillai | C18: CLI-0035 | D18: AI Insights Module | E18: Google Ads | F18: Closed Lost | G18: 416867 | H18: 2024-05-14 | I18: 45541 | J18: 115 | K18: 12.2 | L18: South | M18: Q2-2024
A19: DEAL-00351 | B19: Arjun Rao | C19: CLI-0090 | D19: CloudShift Platform | E19: Trade Show | F19: Proposal Sent | G19: 67690 | H19: 2025-02-20 | K19: 12.5 | L19: South | M19: Q1-2025
A20: DEAL-02148 | B20: Aditya Pillai | C20: CLI-0202 | D20: CloudShift Platform | E20: Email Campaign | F20: Closed Won | G20: 453993 | H20: 2024-01-25 | I20: 45466 | J20: 150 | K20: 9.5 | L20: West | M20: Q1-2024
A21: DEAL-01377 | B21: Vikram Patel | C21: CLI-0102 | D21: AnalyticsEdge | E21: Trade Show | F21: Proposal Sent | G21: 404058 | H21: 05/20/2024 | K21: 5.3 | L21: South | M21: Q2-2024
A22: DEAL-01947 | B22: Arjun Rao | C22: CLI-0135 | D22: CloudShift Platform | E22: LinkedIn Campaign | F22: Qualification | G22: 117974 | H22: 2023-01-24 | K22: 11.5 | L22: East | M22: Q1-2023
A23: DEAL-02354 | B23: Meera Reddy | C23: CLI-0120 | D23: CloudShift Platform | E23: LinkedIn Campaign | F23: Proposal Sent | G23: 111938 | H23: 2025-03-09 | L23: South | M23: Q1-2025
A24: DEAL-01835 | B24: Rahul Patel | C24: CLI-0070 | D24: AI Insights Module | E24: Cold Outreach | F24: Closed Lost | G24: 133407 | H24: 2023-04-30 | I24: 45166 | J24: 120 | K24: 10.9 | L24: North | M24: Q2-2023
A25: DEAL-02057 | B25: Deepika Das | C25: CLI-0125 | D25: SecureNet Suite | F25: Negotiation | G25: 125962 | H25: 2024-02-25 | K25: 12.9 | L25: East | M25: Q1-2024
A26: DEAL-00631 | B26: Aditya Pillai | C26: CLI-0222 | D26: AnalyticsEdge | E26: Trade Show | F26: Closed Won | G26: 71017 | H26: 2023-03-09 | I26: 45095 | J26: 101 | K26: 3.5 | L26: West | M26: Q1-2023
A27: DEAL-02059 | B27: Vikram Iyer | C27: CLI-0191 | D27: AnalyticsEdge | E27: Cold Outreach | F27: Closed Won | G27: 80078 | H27: 2024-12-26 | I27: 45722 | J27: 70 | K27: 4.9 | L27: North | M27: Q4-2024
A28: DEAL-00946 | B28: Rahul Patel | C28: CLI-0158 | D28: SecureNet Suite | E28: Cold Outreach | F28: Negotiation | G28: 147459 | H28: 2023-04-10 | K28: 6.4 | L28: South | M28: Q2-2023
A29: DEAL-01560 | B29: Siddharth Gupta | C29: CLI-0219 | D29: AI Insights Module | E29: Webinar | F29: Closed Lost | G29: 59394 | H29: 2023-12-18 | I29: 45351 | J29: 73 | K29: 2.1 | L29: East | M29: Q4-2023
A30: DEAL-01779 | B30: Neha Pillai | C30: CLI-0266 | D30: CloudShift Platform | E30: LinkedIn Campaign | F30: Prospecting | G30: 490489 | H30: 2025-02-11 | L30: North | M30: Q1-2025
A31: DEAL-01223 | B31: Ananya Sharma | C31: CLI-0006 | D31: DevOps Accelerator | E31: Trade Show | F31: Proposal Sent | G31: 267116 | H31: 2024-07-02 | K31: 3 | L31: South | M31: Q3-2024
A32: DEAL-02345 | B32: Riya Das | C32: CLI-0060 | D32: DevOps Accelerator | E32: Trade Show | F32: Closed Lost | G32: 340697 | H32: 2023-06-17 | I32: 45174 | J32: 80 | K32: 6.7 | L32: North | M32: Q2-2023
A33: DEAL-00816 | B33: Aditya Pillai | C33: CLI-0278 | D33: CloudShift Platform | E33: Referral | F33: Negotiation | G33: 432247 | H33: 2025-03-13 | K33: 13.4 | L33: North | M33: Q1-2025
A34: DEAL-01909 | B34: Amit Pillai | C34: CLI-0063 | D34: AnalyticsEdge | E34: Email Campaign | F34: Closed Lost | G34: 449838 | H34: 2024-05-30 | I34: 45589 | J34: 147 | K34: 6.8 | L34: West | M34: Q2-2024
A35: DEAL-00184 | B35: Siddharth Gupta | C35: CLI-0080 | D35: AI Insights Module | E35: LinkedIn Campaign | F35: Negotiation | G35: 325774 | H35: 2024-02-13 | L35: West | M35: Q1-2024
A36: DEAL-00430 | B36: Siddharth Gupta | C36: CLI-0088 | D36: AnalyticsEdge | E36: Trade Show | F36: Closed Lost | G36: 251845 | H36: 2024-07-26 | I36: 45520 | J36: 21 | K36: 6.3 | L36: East | M36: Q3-2024
A37: DEAL-01657 | B37: Arjun Rao | C37: CLI-0154 | D37: CloudShift Platform | E37: Cold Outreach | F37: Proposal Sent | G37: 245814 | H37: 2023-04-01 | L37: North | M37: Q2-2023
A38: DEAL-01118 | B38: Rohit Mehta | C38: CLI-0086 | D38: AI Insights Module | E38: Webinar | F38: Qualification | G38: 128284 | H38: 2023-06-06 | K38: 1.5 | L38: South | M38: Q2-2023
A39: DEAL-00337 | B39: Meera Reddy | C39: CLI-0286 | D39: SecureNet Suite | F39: Proposal Sent | G39: 157092 | H39: 2024-12-29 | K39: 6.3 | L39: North | M39: Q4-2024
A40: DEAL-01051 | B40: Priya Kumar | C40: CLI-0284 | D40: DevOps Accelerator | E40: Trade Show | F40: Qualification | G40: 387930 | H40: 2024-10-22 | K40: 2.8 | L40: West | M40: Q4-2024
...

Sheet Raw_Finance_Expenses
A1: Expense_ID | B1: Department | C1: Category | D1: Vendor | E1: Amount_INR | F1: Budget_Allocated_INR | G1: Variance_INR | H1: Expense_Date | I1: Approval_Status | J1: Payment_Mode | K1: Fiscal_Year | L1: Remarks
A2: EXP-00594 | C2: Cloud Infrastructure | D2: Slack | E2: 209189 | F2: 170793.17 | G2: 38395.83 | H2: 45126 | I2: Pending | J2: Vendor Credit | K2: FY2023-2024 | L2: Under review
A3: EXP-00495 | B3: Operations | C3: Utilities | D3: HubSpot | E3: 6214 | F3: 7523.05 | G3: -1309.05 | H3: 45209 | I3: Approved | J3: Bank Transfer | K3: FY2023-2024 | L3: Recurring
A4: EXP-00587 | B4: Sales | C4: Marketing Spend | D4: SAP | E4: 499533 | F4: 550589.56 | G4: -51056.56 | H4: 45310 | I4: Approved | J4: Bank Transfer | K4: FY2023-2024 | L4: Recurring
A5: EXP-00178 | B5: Finance | C5: Utilities | D5: Infosys | E5: 403234 | F5: 426617.54 | G5: -23383.54 | H5: 45732 | I5: Approved | J5: Bank Transfer | K5: FY2024-2025
A6: EXP-00869 | C6: Cloud Infrastructure | D6: TCS | E6: 187461 | F6: 156297.94 | G6: 31163.06 | H6: 44963 | I6: Approved | J6: Credit Card | K6: FY2022-2023
A7: EXP-00674 | B7: Sales | C7: Hardware | D7: TCS | E7: 352393 | F7: 449410.33 | G7: -97017.33 | H7: 45365 | I7: Approved | J7: Bank Transfer | K7: FY2023-2024
A8: EXP-00181 | B8: Engineering | C8: Hardware | D8: Slack | E8: 361946 | F8: 354476.37 | G8: 7469.63 | H8: 45152 | I8: Pending | J8: Vendor Credit | K8: FY2023-2024 | L8: Urgent
A9: EXP-00277 | B9: Support | C9: Office Supplies | D9: Wipro | E9: 398503 | F9: 438557.67 | G9: -40054.67 | H9: 45145 | I9: Approved | J9: Credit Card | K9: FY2023-2024
A10: EXP-00515 | B10: Support | C10: Consulting Fees | D10: Oracle | E10: 345565 | F10: 382355.25 | G10: -36790.25 | H10: 45437 | I10: Approved | J10: Vendor Credit | K10: FY2024-2025 | L10: Duplicate entry
A11: EXP-00339 | B11: Engineering | C11: Hardware | D11: HubSpot | E11: 441930 | F11: 426169.24 | G11: 15760.76 | H11: 45740 | I11: Approved | J11: Credit Card | K11: FY2024-2025 | L11: Under review
A12: EXP-00555 | C12: Office Supplies | D12: SAP | E12: 304214 | F12: 345611.18 | G12: -41397.18 | H12: 45689 | I12: Approved | J12: Bank Transfer | K12: FY2024-2025 | L12: Recurring
A13: EXP-00803 | B13: Support | C13: Travel | D13: Freshdesk | E13: 65791 | F13: 59739.7 | G13: 6051.3 | H13: 45346 | I13: Approved | J13: Petty Cash | K13: FY2023-2024 | L13: Under review
A14: EXP-00875 | B14: Engineering | C14: Software Licenses | D14: Google Cloud | E14: 49237 | G14: 7036.11 | H14: 45457 | I14: Pending | J14: Petty Cash | K14: FY2024-2025 | L14: Duplicate entry
A15: EXP-00691 | B15: HR | C15: Office Supplies | D15: TCS | E15: 365283 | F15: 359381.54 | G15: 5901.46 | H15: 45645 | I15: Approved | J15: Credit Card | K15: FY2024-2025
A16: EXP-00233 | B16: HR | C16: Consulting Fees | D16: Google Cloud | E16: 201346 | F16: 197464.53 | H16: 45719 | I16: Pending | J16: Bank Transfer | K16: FY2024-2025 | L16: Under review
A17: EXP-00071 | B17: Sales | C17: Hardware | D17: HubSpot | E17: 375484 | F17: 303740.88 | G17: 71743.12 | H17: 45454 | I17: Pending | J17: Bank Transfer | K17: FY2024-2025 | L17: One-time
A18: EXP-00860 | B18: Operations | C18: Cloud Infrastructure | D18: Wipro | E18: 91274 | F18: 117271.6 | G18: -25997.6 | H18: 45367 | I18: Approved | J18: Petty Cash | K18: FY2023-2024
A19: EXP-00607 | B19: Finance | C19: Hardware | D19: Jira | E19: 58546 | F19: 54790.73 | G19: 3755.27 | H19: 45324 | I19: Approved | J19: Petty Cash | K19: FY2023-2024 | L19: Under review
A20: EXP-00651 | C20: Marketing Spend | D20: SAP | E20: 10904 | F20: 13676.8 | G20: -2772.8 | H20: 44973 | I20: Approved | J20: Vendor Credit | K20: FY2022-2023 | L20: Duplicate entry
A21: EXP-00652 | B21: Operations | C21: Utilities | D21: AWS | E21: 65481 | F21: 81303.61 | G21: -15822.61 | H21: 44962 | I21: Pending | J21: Vendor Credit | K21: FY2022-2023 | L21: Duplicate entry
A22: EXP-00369 | B22: Marketing | C22: Marketing Spend | D22: HubSpot | E22: 66000 | F22: 78840.27 | G22: -12840.27 | H22: 45341 | I22: Approved | J22: Credit Card | K22: FY2023-2024 | L22: Under review
A23: EXP-00721 | B23: Finance | C23: Office Supplies | D23: Slack | E23: 32147 | F23: 36235.03 | G23: -4088.03 | H23: 45247 | I23: Approved | J23: Credit Card | K23: FY2023-2024
A24: EXP-00390 | C24: Consulting Fees | D24: Wipro | E24: 312310 | F24: 339411.41 | G24: -27101.41 | H24: 45270 | I24: Pending | J24: Bank Transfer | K24: FY2023-2024 | L24: Duplicate entry
A25: EXP-00520 | B25: HR | C25: Utilities | D25: Infosys | E25: 145866 | F25: 176369.11 | G25: -30503.11 | H25: 45589 | I25: Approved | J25: Petty Cash | K25: FY2024-2025 | L25: Recurring
A26: EXP-00971 | B26: Finance | C26: Training | D26: Oracle | E26: -270391 | F26: 224861.48 | G26: 45529.52 | H26: 44992 | I26: Approved | J26: Credit Card | K26: FY2022-2023 | L26: Duplicate entry
A27: EXP-00411 | B27: HR | C27: Hardware | D27: Microsoft Azure | E27: 410046 | F27: 483620.72 | G27: -73574.72 | H27: 45456 | I27: Approved | J27: Petty Cash | K27: FY2024-2025
A28: EXP-00354 | B28: Sales | C28: Salaries | D28: Oracle | E28: 406494 | G28: -13532 | H28: 45553 | I28: Approved | J28: Credit Card | K28: FY2024-2025 | L28: Recurring
A29: EXP-00600 | B29: Engineering | C29: Travel | D29: Zoom | E29: 66859 | F29: 75521.94 | G29: -8662.94 | H29: 45442 | I29: Approved | J29: Petty Cash | K29: FY2024-2025
A30: EXP-00034 | B30: Support | C30: Consulting Fees | D30: Oracle | E30: 389612 | F30: 356713.15 | G30: 32898.85 | H30: 45486 | I30: Pending | J30: Petty Cash | K30: FY2024-2025
A31: EXP-00200 | B31: Sales | C31: Salaries | D31: TCS | E31: 397643 | F31: 366588.32 | H31: 45309 | I31: Pending | J31: Petty Cash | K31: FY2023-2024
A32: EXP-00925 | B32: Sales | C32: Software Licenses | D32: Google Cloud | E32: 367122 | F32: 465065.53 | G32: -97943.53 | H32: 45084 | I32: Pending | J32: Credit Card | K32: FY2023-2024 | L32: One-time
A33: EXP-00546 | B33: Marketing | C33: Travel | D33: Adobe | E33: 65667 | F33: 72499.12 | G33: -6832.12 | H33: 45077 | I33: Approved | J33: Petty Cash | K33: FY2023-2024
A34: EXP-00602 | C34: Salaries | D34: Wipro | E34: 350446 | F34: 293167.5 | G34: 57278.5 | H34: 45395 | I34: Approved | J34: Vendor Credit | K34: FY2024-2025
A35: EXP-00083 | B35: Support | C35: Maintenance | D35: Wipro | E35: 215496 | F35: 269360.68 | H35: 45427 | I35: Rejected | J35: Petty Cash | K35: FY2024-2025 | L35: Duplicate entry
A36: EXP-00750 | B36: Sales | C36: Recruitment | D36: Freshdesk | E36: 7227 | F36: 9023.9 | G36: -1796.9 | H36: 45131 | I36: Approved | J36: Vendor Credit | K36: FY2023-2024
A37: EXP-00172 | B37: Operations | C37: Travel | D37: AWS | E37: 481644 | F37: 431586.58 | G37: 50057.42 | H37: 45338 | I37: Approved | J37: Vendor Credit | K37: FY2023-2024 | L37: Urgent
A38: EXP-00531 | B38: Sales | C38: Recruitment | D38: AWS | E38: -214583 | F38: 220195.61 | G38: -5612.61 | H38: 45157 | I38: Approved | J38: Petty Cash | K38: FY2023-2024
A39: EXP-00337 | B39: Sales | C39: Utilities | D39: HubSpot | E39: 71717 | F39: 89231.77 | G39: -17514.77 | H39: 45573 | I39: Approved | J39: Credit Card | K39: FY2024-2025 | L39: Urgent
A40: EXP-00832 | B40: Engineering | C40: Training | D40: Infosys | E40: 352092 | F40: 424330.22 | G40: -72238.22 | H40: 45540 | I40: Approved | J40: Bank Transfer | K40: FY2024-2025 | L40: One-time
...

Sheet Cleaned_Sales_Deals
A1: Deal_ID | B1: Sales_Rep | C1: Client_ID | D1: Product | E1: Lead_Source | F1: Deal_Stage | G1: Deal_Value_INR | H1: Created_Date | I1: Close_Date | J1: Days_to_Close | K1: Discount_Percent | L1: Region | M1: Quarter | N1: Outlier_Flag
A2: DEAL-01440 | B2: Rohit Mehta | C2: CLI-0014 | D2: SecureNet Suite | E2: Referral | F2: Closed Lost | G2: 160271 | H2: 45263 | I2: 45406 | J2: 143 | K2: 3.7 | L2: West | M2: Q4-2023 | N2: =IF(G2>$R$5,"High Outlier",IF(G2<$R$6,"Low Outlier","Normal")) -> Normal | Q2: Deal Value Outlier Statistics | R2: Value
A3: DEAL-02021 | B3: Amit Pillai | C3: CLI-0208 | D3: AI Insights Module | E3: Organic Search | F3: Prospecting | G3: 491510 | H3: 45030 | L3: South | M3: Q2-2023 | N3: =IF(G3>$R$5,"High Outlier",IF(G3<$R$6,"Low Outlier","Normal")) -> Normal | Q3: Mean Deal Value (INR) | R3: =AVERAGE(G2:G2501) -> 278456.13
A4: DEAL-00174 | B4: Amit Pillai | C4: CLI-0084 | D4: AI Insights Module | E4: Referral | F4: Proposal Sent | G4: 224184 | H4: 44956 | L4: West | M4: Q1-2023 | N4: =IF(G4>$R$5,"High Outlier",IF(G4<$R$6,"Low Outlier","Normal")) -> Normal | Q4: Std Dev (INR) | R4: =STDEV(G2:G2501) -> 211155.77
A5: DEAL-02399 | B5: Vikram Patel | C5: CLI-0096 | D5: AnalyticsEdge | E5: Organic Search | F5: Closed Won | G5: 265745 | H5: 45590 | I5: 45650 | J5: 60 | K5: 17.8 | L5: South | M5: Q4-2024 | N5: =IF(G5>$R$5,"High Outlier",IF(G5<$R$6,"Low Outlier","Normal")) -> Normal | Q5: Upper Threshold (Mean+3*STD) | R5: =R3+3*R4 -> 911923.43
A6: DEAL-00243 | B6: Siddharth Joshi | C6: CLI-0071 | D6: DataVault Pro | E6: Email Campaign | F6: Closed Won | G6: 255053 | H6: 45266 | I6: 45429 | J6: 163 | K6: 8.4 | L6: East | M6: Q4-2023 | N6: =IF(G6>$R$5,"High Outlier",IF(G6<$R$6,"Low Outlier","Normal")) -> Normal | Q6: Lower Threshold (Mean-3*STD) | R6: =R3-3*R4 -> -355011.17
A7: DEAL-02410 | B7: Unassigned | C7: CLI-0238 | D7: DataVault Pro | E7: Organic Search | F7: Qualification | G7: 389913 | H7: 45276 | L7: South | M7: Q4-2023 | N7: =IF(G7>$R$5,"High Outlier",IF(G7<$R$6,"Low Outlier","Normal")) -> Normal
A8: DEAL-02158 | B8: Amit Pillai | C8: CLI-0081 | D8: AI Insights Module | E8: Email Campaign | F8: Closed Won | G8: 393048 | H8: 45613 | I8: 45784 | J8: 171 | K8: 1.1 | L8: West | M8: Q4-2024 | N8: =IF(G8>$R$5,"High Outlier",IF(G8<$R$6,"Low Outlier","Normal")) -> Normal
A9: DEAL-01161 | B9: Aditya Pillai | C9: CLI-0236 | D9: AI Insights Module | E9: Google Ads | F9: Closed Won | G9: 295502 | H9: 45696 | I9: 45821 | J9: 125 | K9: 15.8 | L9: East | M9: Q1-2025 | N9: =IF(G9>$R$5,"High Outlier",IF(G9<$R$6,"Low Outlier","Normal")) -> Normal
A10: DEAL-00586 | B10: Meera Reddy | C10: CLI-0128 | D10: CloudShift Platform | E10: Organic Search | F10: Proposal Sent | G10: 172519 | H10: 45371 | K10: 14.2 | L10: South | M10: Q1-2024 | N10: =IF(G10>$R$5,"High Outlier",IF(G10<$R$6,"Low Outlier","Normal")) -> Normal
A11: DEAL-00863 | B11: Aditya Pillai | C11: CLI-0147 | D11: DataVault Pro | E11: LinkedIn Campaign | F11: Closed Won | G11: 146890 | H11: 45356 | I11: 45414 | J11: 58 | K11: 8.5 | L11: West | M11: Q1-2024 | N11: =IF(G11>$R$5,"High Outlier",IF(G11<$R$6,"Low Outlier","Normal")) -> Normal
A12: DEAL-01273 | B12: Ananya Sharma | C12: CLI-0237 | D12: AnalyticsEdge | E12: Webinar | F12: Closed Won | G12: 242460 | H12: 45346 | I12: 45463 | J12: 117 | K12: 23 | L12: East | M12: Q1-2024 | N12: =IF(G12>$R$5,"High Outlier",IF(G12<$R$6,"Low Outlier","Normal")) -> Normal
A13: DEAL-01938 | B13: Siddharth Gupta | C13: CLI-0261 | D13: DataVault Pro | E13: LinkedIn Campaign | F13: Closed Won | G13: 396833 | H13: 45219 | I13: 45236 | J13: 17 | K13: 4.3 | L13: South | M13: Q4-2023 | N13: =IF(G13>$R$5,"High Outlier",IF(G13<$R$6,"Low Outlier","Normal")) -> Normal
A14: DEAL-01122 | B14: Rahul Patel | C14: CLI-0070 | D14: AI Insights Module | E14: Webinar | F14: Closed Won | G14: 207588 | H14: 45335 | I14: 45486 | J14: 151 | K14: 4.3 | L14: East | M14: Q1-2024 | N14: =IF(G14>$R$5,"High Outlier",IF(G14<$R$6,"Low Outlier","Normal")) -> Normal
A15: DEAL-01643 | B15: Riya Das | C15: CLI-0298 | D15: DevOps Accelerator | E15: Referral | F15: Closed Won | G15: 244787 | H15: 45210 | I15: 45327 | J15: 117 | K15: 7.8 | L15: East | M15: Q4-2023 | N15: =IF(G15>$R$5,"High Outlier",IF(G15<$R$6,"Low Outlier","Normal")) -> Normal
A16: DEAL-00234 | B16: Ananya Sharma | C16: CLI-0286 | D16: SecureNet Suite | E16: Trade Show | F16: Closed Won | G16: 223320 | H16: 45623 | I16: 45770 | J16: 147 | K16: 9 | L16: North | M16: Q4-2024 | N16: =IF(G16>$R$5,"High Outlier",IF(G16<$R$6,"Low Outlier","Normal")) -> Normal
A17: DEAL-01783 | B17: Vikram Iyer | C17: CLI-0050 | D17: AI Insights Module | E17: Cold Outreach | F17: Proposal Sent | G17: 341493 | H17: 45142 | L17: West | M17: Q3-2023 | N17: =IF(G17>$R$5,"High Outlier",IF(G17<$R$6,"Low Outlier","Normal")) -> Normal
A18: DEAL-00305 | B18: Neha Pillai | C18: CLI-0035 | D18: AI Insights Module | E18: Google Ads | F18: Closed Lost | G18: 416867 | H18: 45426 | I18: 45541 | J18: 115 | K18: 12.2 | L18: South | M18: Q2-2024 | N18: =IF(G18>$R$5,"High Outlier",IF(G18<$R$6,"Low Outlier","Normal")) -> Normal
A19: DEAL-00351 | B19: Arjun Rao | C19: CLI-0090 | D19: CloudShift Platform | E19: Trade Show | F19: Proposal Sent | G19: 67690 | H19: 45708 | K19: 12.5 | L19: South | M19: Q1-2025 | N19: =IF(G19>$R$5,"High Outlier",IF(G19<$R$6,"Low Outlier","Normal")) -> Normal
A20: DEAL-02148 | B20: Aditya Pillai | C20: CLI-0202 | D20: CloudShift Platform | E20: Email Campaign | F20: Closed Won | G20: 453993 | H20: 45316 | I20: 45466 | J20: 150 | K20: 9.5 | L20: West | M20: Q1-2024 | N20: =IF(G20>$R$5,"High Outlier",IF(G20<$R$6,"Low Outlier","Normal")) -> Normal
A21: DEAL-01377 | B21: Vikram Patel | C21: CLI-0102 | D21: AnalyticsEdge | E21: Trade Show | F21: Proposal Sent | G21: 404058 | H21: 45432 | K21: 5.3 | L21: South | M21: Q2-2024 | N21: =IF(G21>$R$5,"High Outlier",IF(G21<$R$6,"Low Outlier","Normal")) -> Normal
A22: DEAL-01947 | B22: Arjun Rao | C22: CLI-0135 | D22: CloudShift Platform | E22: LinkedIn Campaign | F22: Qualification | G22: 117974 | H22: 44950 | K22: 11.5 | L22: East | M22: Q1-2023 | N22: =IF(G22>$R$5,"High Outlier",IF(G22<$R$6,"Low Outlier","Normal")) -> Normal
A23: DEAL-02354 | B23: Meera Reddy | C23: CLI-0120 | D23: CloudShift Platform | E23: LinkedIn Campaign | F23: Proposal Sent | G23: 111938 | H23: 45725 | L23: South | M23: Q1-2025 | N23: =IF(G23>$R$5,"High Outlier",IF(G23<$R$6,"Low Outlier","Normal")) -> Normal
A24: DEAL-01835 | B24: Rahul Patel | C24: CLI-0070 | D24: AI Insights Module | E24: Cold Outreach | F24: Closed Lost | G24: 133407 | H24: 45046 | I24: 45166 | J24: 120 | K24: 10.9 | L24: North | M24: Q2-2023 | N24: =IF(G24>$R$5,"High Outlier",IF(G24<$R$6,"Low Outlier","Normal")) -> Normal
A25: DEAL-02057 | B25: Deepika Das | C25: CLI-0125 | D25: SecureNet Suite | E25: Unknown | F25: Negotiation | G25: 125962 | H25: 45347 | K25: 12.9 | L25: East | M25: Q1-2024 | N25: =IF(G25>$R$5,"High Outlier",IF(G25<$R$6,"Low Outlier","Normal")) -> Normal
A26: DEAL-00631 | B26: Aditya Pillai | C26: CLI-0222 | D26: AnalyticsEdge | E26: Trade Show | F26: Closed Won | G26: 71017 | H26: 44994 | I26: 45095 | J26: 101 | K26: 3.5 | L26: West | M26: Q1-2023 | N26: =IF(G26>$R$5,"High Outlier",IF(G26<$R$6,"Low Outlier","Normal")) -> Normal
A27: DEAL-02059 | B27: Vikram Iyer | C27: CLI-0191 | D27: AnalyticsEdge | E27: Cold Outreach | F27: Closed Won | G27: 80078 | H27: 45652 | I27: 45722 | J27: 70 | K27: 4.9 | L27: North | M27: Q4-2024 | N27: =IF(G27>$R$5,"High Outlier",IF(G27<$R$6,"Low Outlier","Normal")) -> Normal
A28: DEAL-00946 | B28: Rahul Patel | C28: CLI-0158 | D28: SecureNet Suite | E28: Cold Outreach | F28: Negotiation | G28: 147459 | H28: 45026 | K28: 6.4 | L28: South | M28: Q2-2023 | N28: =IF(G28>$R$5,"High Outlier",IF(G28<$R$6,"Low Outlier","Normal")) -> Normal
A29: DEAL-01560 | B29: Siddharth Gupta | C29: CLI-0219 | D29: AI Insights Module | E29: Webinar | F29: Closed Lost | G29: 59394 | H29: 45278 | I29: 45351 | J29: 73 | K29: 2.1 | L29: East | M29: Q4-2023 | N29: =IF(G29>$R$5,"High Outlier",IF(G29<$R$6,"Low Outlier","Normal")) -> Normal
A30: DEAL-01779 | B30: Neha Pillai | C30: CLI-0266 | D30: CloudShift Platform | E30: LinkedIn Campaign | F30: Prospecting | G30: 490489 | H30: 45699 | L30: North | M30: Q1-2025 | N30: =IF(G30>$R$5,"High Outlier",IF(G30<$R$6,"Low Outlier","Normal")) -> Normal
A31: DEAL-01223 | B31: Ananya Sharma | C31: CLI-0006 | D31: DevOps Accelerator | E31: Trade Show | F31: Proposal Sent | G31: 267116 | H31: 45475 | K31: 3 | L31: South | M31: Q3-2024 | N31: =IF(G31>$R$5,"High Outlier",IF(G31<$R$6,"Low Outlier","Normal")) -> Normal
A32: DEAL-02345 | B32: Riya Das | C32: CLI-0060 | D32: DevOps Accelerator | E32: Trade Show | F32: Closed Lost | G32: 340697 | H32: 45094 | I32: 45174 | J32: 80 | K32: 6.7 | L32: North | M32: Q2-2023 | N32: =IF(G32>$R$5,"High Outlier",IF(G32<$R$6,"Low Outlier","Normal")) -> Normal
A33: DEAL-00816 | B33: Aditya Pillai | C33: CLI-0278 | D33: CloudShift Platform | E33: Referral | F33: Negotiation | G33: 432247 | H33: 45729 | K33: 13.4 | L33: North | M33: Q1-2025 | N33: =IF(G33>$R$5,"High Outlier",IF(G33<$R$6,"Low Outlier","Normal")) -> Normal
A34: DEAL-01909 | B34: Amit Pillai | C34: CLI-0063 | D34: AnalyticsEdge | E34: Email Campaign | F34: Closed Lost | G34: 449838 | H34: 45442 | I34: 45589 | J34: 147 | K34: 6.8 | L34: West | M34: Q2-2024 | N34: =IF(G34>$R$5,"High Outlier",IF(G34<$R$6,"Low Outlier","Normal")) -> Normal
A35: DEAL-00184 | B35: Siddharth Gupta | C35: CLI-0080 | D35: AI Insights Module | E35: LinkedIn Campaign | F35: Negotiation | G35: 325774 | H35: 45335 | L35: West | M35: Q1-2024 | N35: =IF(G35>$R$5,"High Outlier",IF(G35<$R$6,"Low Outlier","Normal")) -> Normal
A36: DEAL-00430 | B36: Siddharth Gupta | C36: CLI-0088 | D36: AnalyticsEdge | E36: Trade Show | F36: Closed Lost | G36: 251845 | H36: 45499 | I36: 45520 | J36: 21 | K36: 6.3 | L36: East | M36: Q3-2024 | N36: =IF(G36>$R$5,"High Outlier",IF(G36<$R$6,"Low Outlier","Normal")) -> Normal
A37: DEAL-01657 | B37: Arjun Rao | C37: CLI-0154 | D37: CloudShift Platform | E37: Cold Outreach | F37: Proposal Sent | G37: 245814 | H37: 45017 | L37: North | M37: Q2-2023 | N37: =IF(G37>$R$5,"High Outlier",IF(G37<$R$6,"Low Outlier","Normal")) -> Normal
A38: DEAL-01118 | B38: Rohit Mehta | C38: CLI-0086 | D38: AI Insights Module | E38: Webinar | F38: Qualification | G38: 128284 | H38: 45083 | K38: 1.5 | L38: South | M38: Q2-2023 | N38: =IF(G38>$R$5,"High Outlier",IF(G38<$R$6,"Low Outlier","Normal")) -> Normal
A39: DEAL-00337 | B39: Meera Reddy | C39: CLI-0286 | D39: SecureNet Suite | E39: Unknown | F39: Proposal Sent | G39: 157092 | H39: 45655 | K39: 6.3 | L39: North | M39: Q4-2024 | N39: =IF(G39>$R$5,"High Outlier",IF(G39<$R$6,"Low Outlier","Normal")) -> Normal
A40: DEAL-01051 | B40: Priya Kumar | C40: CLI-0284 | D40: DevOps Accelerator | E40: Trade Show | F40: Qualification | G40: 387930 | H40: 45587 | K40: 2.8 | L40: West | M40: Q4-2024 | N40: =IF(G40>$R$5,"High Outlier",IF(G40<$R$6,"Low Outlier","Normal")) -> Normal
...

Sheet Cleaned_Finance_Expenses
A1: Expense_ID | B1: Department | C1: Category | D1: Vendor | E1: Amount_INR | F1: Budget_Allocated_INR | G1: Recomputed_Variance_INR | H1: Variance_INR | I1: Expense_Date | J1: Approval_Status | K1: Payment_Mode | L1: Fiscal_Year | M1: Remarks | N1: Amount_Type_Flag | O1: High_Value_Pending_Rejected_Flag
A2: EXP-00594 | B2: Unspecified | C2: Cloud Infrastructure | D2: Slack | E2: 209189 | F2: 170793.17 | G2: =IF(F2="","",E2-F2) -> 38395.83 | H2: 38395.83 | I2: 45126 | J2: Pending | K2: Vendor Credit | L2: FY2023-2024 | M2: Under review | N2: =IF(E2<0,"Credit/Refund","Expense") -> Expense | O2: =IF(AND(OR(J2="Pending",J2="Rejected"),E2>200000),"Flag: High-Value "&J2,"") -> Flag: High-Value Pending
A3: EXP-00495 | B3: Operations | C3: Utilities | D3: HubSpot | E3: 6214 | F3: 7523.05 | G3: =IF(F3="","",E3-F3) -> -1309.05 | H3: -1309.05 | I3: 45209 | J3: Approved | K3: Bank Transfer | L3: FY2023-2024 | M3: Recurring | N3: =IF(E3<0,"Credit/Refund","Expense") -> Expense | O3: =IF(AND(OR(J3="Pending",J3="Rejected"),E3>200000),"Flag: High-Value "&J3,"")
A4: EXP-00587 | B4: Sales | C4: Marketing Spend | D4: SAP | E4: 499533 | F4: 550589.56 | G4: =IF(F4="","",E4-F4) -> -51056.56 | H4: -51056.56 | I4: 45310 | J4: Approved | K4: Bank Transfer | L4: FY2023-2024 | M4: Recurring | N4: =IF(E4<0,"Credit/Refund","Expense") -> Expense | O4: =IF(AND(OR(J4="Pending",J4="Rejected"),E4>200000),"Flag: High-Value "&J4,"")
A5: EXP-00178 | B5: Finance | C5: Utilities | D5: Infosys | E5: 403234 | F5: 426617.54 | G5: =IF(F5="","",E5-F5) -> -23383.54 | H5: -23383.54 | I5: 45732 | J5: Approved | K5: Bank Transfer | L5: FY2024-2025 | N5: =IF(E5<0,"Credit/Refund","Expense") -> Expense | O5: =IF(AND(OR(J5="Pending",J5="Rejected"),E5>200000),"Flag: High-Value "&J5,"")
A6: EXP-00869 | B6: Unspecified | C6: Cloud Infrastructure | D6: TCS | E6: 187461 | F6: 156297.94 | G6: =IF(F6="","",E6-F6) -> 31163.06 | H6: 31163.06 | I6: 44963 | J6: Approved | K6: Credit Card | L6: FY2022-2023 | N6: =IF(E6<0,"Credit/Refund","Expense") -> Expense | O6: =IF(AND(OR(J6="Pending",J6="Rejected"),E6>200000),"Flag: High-Value "&J6,"")
A7: EXP-00674 | B7: Sales | C7: Hardware | D7: TCS | E7: 352393 | F7: 449410.33 | G7: =IF(F7="","",E7-F7) -> -97017.33 | H7: -97017.33 | I7: 45365 | J7: Approved | K7: Bank Transfer | L7: FY2023-2024 | N7: =IF(E7<0,"Credit/Refund","Expense") -> Expense | O7: =IF(AND(OR(J7="Pending",J7="Rejected"),E7>200000),"Flag: High-Value "&J7,"")
A8: EXP-00181 | B8: Engineering | C8: Hardware | D8: Slack | E8: 361946 | F8: 354476.37 | G8: =IF(F8="","",E8-F8) -> 7469.63 | H8: 7469.63 | I8: 45152 | J8: Pending | K8: Vendor Credit | L8: FY2023-2024 | M8: Urgent | N8: =IF(E8<0,"Credit/Refund","Expense") -> Expense | O8: =IF(AND(OR(J8="Pending",J8="Rejected"),E8>200000),"Flag: High-Value "&J8,"") -> Flag: High-Value Pending
A9: EXP-00277 | B9: Support | C9: Office Supplies | D9: Wipro | E9: 398503 | F9: 438557.67 | G9: =IF(F9="","",E9-F9) -> -40054.67 | H9: -40054.67 | I9: 45145 | J9: Approved | K9: Credit Card | L9: FY2023-2024 | N9: =IF(E9<0,"Credit/Refund","Expense") -> Expense | O9: =IF(AND(OR(J9="Pending",J9="Rejected"),E9>200000),"Flag: High-Value "&J9,"")
A10: EXP-00515 | B10: Support | C10: Consulting Fees | D10: Oracle | E10: 345565 | F10: 382355.25 | G10: =IF(F10="","",E10-F10) -> -36790.25 | H10: -36790.25 | I10: 45437 | J10: Approved | K10: Vendor Credit | L10: FY2024-2025 | M10: Duplicate entry | N10: =IF(E10<0,"Credit/Refund","Expense") -> Expense | O10: =IF(AND(OR(J10="Pending",J10="Rejected"),E10>200000),"Flag: High-Value "&J10,"")
A11: EXP-00339 | B11: Engineering | C11: Hardware | D11: HubSpot | E11: 441930 | F11: 426169.24 | G11: =IF(F11="","",E11-F11) -> 15760.76 | H11: 15760.76 | I11: 45740 | J11: Approved | K11: Credit Card | L11: FY2024-2025 | M11: Under review | N11: =IF(E11<0,"Credit/Refund","Expense") -> Expense | O11: =IF(AND(OR(J11="Pending",J11="Rejected"),E11>200000),"Flag: High-Value "&J11,"")
A12: EXP-00555 | B12: Unspecified | C12: Office Supplies | D12: SAP | E12: 304214 | F12: 345611.18 | G12: =IF(F12="","",E12-F12) -> -41397.18 | H12: -41397.18 | I12: 45689 | J12: Approved | K12: Bank Transfer | L12: FY2024-2025 | M12: Recurring | N12: =IF(E12<0,"Credit/Refund","Expense") -> Expense | O12: =IF(AND(OR(J12="Pending",J12="Rejected"),E12>200000),"Flag: High-Value "&J12,"")
A13: EXP-00803 | B13: Support | C13: Travel | D13: Freshdesk | E13: 65791 | F13: 59739.7 | G13: =IF(F13="","",E13-F13) -> 6051.3 | H13: 6051.3 | I13: 45346 | J13: Approved | K13: Petty Cash | L13: FY2023-2024 | M13: Under review | N13: =IF(E13<0,"Credit/Refund","Expense") -> Expense | O13: =IF(AND(OR(J13="Pending",J13="Rejected"),E13>200000),"Flag: High-Value "&J13,"")
A14: EXP-00875 | B14: Engineering | C14: Software Licenses | D14: Google Cloud | E14: 49237 | G14: =IF(F14="","",E14-F14) | H14: 7036.11 | I14: 45457 | J14: Pending | K14: Petty Cash | L14: FY2024-2025 | M14: Duplicate entry | N14: =IF(E14<0,"Credit/Refund","Expense") -> Expense | O14: =IF(AND(OR(J14="Pending",J14="Rejected"),E14>200000),"Flag: High-Value "&J14,"")
A15: EXP-00691 | B15: HR | C15: Office Supplies | D15: TCS | E15: 365283 | F15: 359381.54 | G15: =IF(F15="","",E15-F15) -> 5901.46 | H15: 5901.46 | I15: 45645 | J15: Approved | K15: Credit Card | L15: FY2024-2025 | N15: =IF(E15<0,"Credit/Refund","Expense") -> Expense | O15: =IF(AND(OR(J15="Pending",J15="Rejected"),E15>200000),"Flag: High-Value "&J15,"")
A16: EXP-00233 | B16: HR | C16: Consulting Fees | D16: Google Cloud | E16: 201346 | F16: 197464.53 | G16: =IF(F16="","",E16-F16) -> 3881.47 | I16: 45719 | J16: Pending | K16: Bank Transfer | L16: FY2024-2025 | M16: Under review | N16: =IF(E16<0,"Credit/Refund","Expense") -> Expense | O16: =IF(AND(OR(J16="Pending",J16="Rejected"),E16>200000),"Flag: High-Value "&J16,"") -> Flag: High-Value Pending
A17: EXP-00071 | B17: Sales | C17: Hardware | D17: HubSpot | E17: 375484 | F17: 303740.88 | G17: =IF(F17="","",E17-F17) -> 71743.12 | H17: 71743.12 | I17: 45454 | J17: Pending | K17: Bank Transfer | L17: FY2024-2025 | M17: One-time | N17: =IF(E17<0,"Credit/Refund","Expense") -> Expense | O17: =IF(AND(OR(J17="Pending",J17="Rejected"),E17>200000),"Flag: High-Value "&J17,"") -> Flag: High-Value Pending
A18: EXP-00860 | B18: Operations | C18: Cloud Infrastructure | D18: Wipro | E18: 91274 | F18: 117271.6 | G18: =IF(F18="","",E18-F18) -> -25997.6 | H18: -25997.6 | I18: 45367 | J18: Approved | K18: Petty Cash | L18: FY2023-2024 | N18: =IF(E18<0,"Credit/Refund","Expense") -> Expense | O18: =IF(AND(OR(J18="Pending",J18="Rejected"),E18>200000),"Flag: High-Value "&J18,"")
A19: EXP-00607 | B19: Finance | C19: Hardware | D19: Jira | E19: 58546 | F19: 54790.73 | G19: =IF(F19="","",E19-F19) -> 3755.27 | H19: 3755.27 | I19: 45324 | J19: Approved | K19: Petty Cash | L19: FY2023-2024 | M19: Under review | N19: =IF(E19<0,"Credit/Refund","Expense") -> Expense | O19: =IF(AND(OR(J19="Pending",J19="Rejected"),E19>200000),"Flag: High-Value "&J19,"")
A20: EXP-00651 | B20: Unspecified | C20: Marketing Spend | D20: SAP | E20: 10904 | F20: 13676.8 | G20: =IF(F20="","",E20-F20) -> -2772.8 | H20: -2772.8 | I20: 44973 | J20: Approved | K20: Vendor Credit | L20: FY2022-2023 | M20: Duplicate entry | N20: =IF(E20<0,"Credit/Refund","Expense") -> Expense | O20: =IF(AND(OR(J20="Pending",J20="Rejected"),E20>200000),"Flag: High-Value "&J20,"")
A21: EXP-00652 | B21: Operations | C21: Utilities | D21: AWS | E21: 65481 | F21: 81303.61 | G21: =IF(F21="","",E21-F21) -> -15822.61 | H21: -15822.61 | I21: 44962 | J21: Pending | K21: Vendor Credit | L21: FY2022-2023 | M21: Duplicate entry | N21: =IF(E21<0,"Credit/Refund","Expense") -> Expense | O21: =IF(AND(OR(J21="Pending",J21="Rejected"),E21>200000),"Flag: High-Value "&J21,"")
A22: EXP-00369 | B22: Marketing | C22: Marketing Spend | D22: HubSpot | E22: 66000 | F22: 78840.27 | G22: =IF(F22="","",E22-F22) -> -12840.27 | H22: -12840.27 | I22: 45341 | J22: Approved | K22: Credit Card | L22: FY2023-2024 | M22: Under review | N22: =IF(E22<0,"Credit/Refund","Expense") -> Expense | O22: =IF(AND(OR(J22="Pending",J22="Rejected"),E22>200000),"Flag: High-Value "&J22,"")
A23: EXP-00721 | B23: Finance | C23: Office Supplies | D23: Slack | E23: 32147 | F23: 36235.03 | G23: =IF(F23="","",E23-F23) -> -4088.03 | H23: -4088.03 | I23: 45247 | J23: Approved | K23: Credit Card | L23: FY2023-2024 | N23: =IF(E23<0,"Credit/Refund","Expense") -> Expense | O23: =IF(AND(OR(J23="Pending",J23="Rejected"),E23>200000),"Flag: High-Value "&J23,"")
A24: EXP-00390 | B24: Unspecified | C24: Consulting Fees | D24: Wipro | E24: 312310 | F24: 339411.41 | G24: =IF(F24="","",E24-F24) -> -27101.41 | H24: -27101.41 | I24: 45270 | J24: Pending | K24: Bank Transfer | L24: FY2023-2024 | M24: Duplicate entry | N24: =IF(E24<0,"Credit/Refund","Expense") -> Expense | O24: =IF(AND(OR(J24="Pending",J24="Rejected"),E24>200000),"Flag: High-Value "&J24,"") -> Flag: High-Value Pending
A25: EXP-00520 | B25: HR | C25: Utilities | D25: Infosys | E25: 145866 | F25: 176369.11 | G25: =IF(F25="","",E25-F25) -> -30503.11 | H25: -30503.11 | I25: 45589 | J25: Approved | K25: Petty Cash | L25: FY2024-2025 | M25: Recurring | N25: =IF(E25<0,"Credit/Refund","Expense") -> Expense | O25: =IF(AND(OR(J25="Pending",J25="Rejected"),E25>200000),"Flag: High-Value "&J25,"")
A26: EXP-00971 | B26: Finance | C26: Training | D26: Oracle | E26: -270391 | F26: 224861.48 | G26: =IF(F26="","",E26-F26) -> -495252.48 | H26: 45529.52 | I26: 44992 | J26: Approved | K26: Credit Card | L26: FY2022-2023 | M26: Duplicate entry | N26: =IF(E26<0,"Credit/Refund","Expense") -> Credit/Refund | O26: =IF(AND(OR(J26="Pending",J26="Rejected"),E26>200000),"Flag: High-Value "&J26,"")
A27: EXP-00411 | B27: HR | C27: Hardware | D27: Microsoft Azure | E27: 410046 | F27: 483620.72 | G27: =IF(F27="","",E27-F27) -> -73574.72 | H27: -73574.72 | I27: 45456 | J27: Approved | K27: Petty Cash | L27: FY2024-2025 | N27: =IF(E27<0,"Credit/Refund","Expense") -> Expense | O27: =IF(AND(OR(J27="Pending",J27="Rejected"),E27>200000),"Flag: High-Value "&J27,"")
A28: EXP-00354 | B28: Sales | C28: Salaries | D28: Oracle | E28: 406494 | G28: =IF(F28="","",E28-F28) | H28: -13532 | I28: 45553 | J28: Approved | K28: Credit Card | L28: FY2024-2025 | M28: Recurring | N28: =IF(E28<0,"Credit/Refund","Expense") -> Expense | O28: =IF(AND(OR(J28="Pending",J28="Rejected"),E28>200000),"Flag: High-Value "&J28,"")
A29: EXP-00600 | B29: Engineering | C29: Travel | D29: Zoom | E29: 66859 | F29: 75521.94 | G29: =IF(F29="","",E29-F29) -> -8662.94 | H29: -8662.94 | I29: 45442 | J29: Approved | K29: Petty Cash | L29: FY2024-2025 | N29: =IF(E29<0,"Credit/Refund","Expense") -> Expense | O29: =IF(AND(OR(J29="Pending",J29="Rejected"),E29>200000),"Flag: High-Value "&J29,"")
A30: EXP-00034 | B30: Support | C30: Consulting Fees | D30: Oracle | E30: 389612 | F30: 356713.15 | G30: =IF(F30="","",E30-F30) -> 32898.85 | H30: 32898.85 | I30: 45486 | J30: Pending | K30: Petty Cash | L30: FY2024-2025 | N30: =IF(E30<0,"Credit/Refund","Expense") -> Expense | O30: =IF(AND(OR(J30="Pending",J30="Rejected"),E30>200000),"Flag: High-Value "&J30,"") -> Flag: High-Value Pending
A31: EXP-00200 | B31: Sales | C31: Salaries | D31: TCS | E31: 397643 | F31: 366588.32 | G31: =IF(F31="","",E31-F31) -> 31054.68 | I31: 45309 | J31: Pending | K31: Petty Cash | L31: FY2023-2024 | N31: =IF(E31<0,"Credit/Refund","Expense") -> Expense | O31: =IF(AND(OR(J31="Pending",J31="Rejected"),E31>200000),"Flag: High-Value "&J31,"") -> Flag: High-Value Pending
A32: EXP-00925 | B32: Sales | C32: Software Licenses | D32: Google Cloud | E32: 367122 | F32: 465065.53 | G32: =IF(F32="","",E32-F32) -> -97943.53 | H32: -97943.53 | I32: 45084 | J32: Pending | K32: Credit Card | L32: FY2023-2024 | M32: One-time | N32: =IF(E32<0,"Credit/Refund","Expense") -> Expense | O32: =IF(AND(OR(J32="Pending",J32="Rejected"),E32>200000),"Flag: High-Value "&J32,"") -> Flag: High-Value Pending
A33: EXP-00546 | B33: Marketing | C33: Travel | D33: Adobe | E33: 65667 | F33: 72499.12 | G33: =IF(F33="","",E33-F33) -> -6832.12 | H33: -6832.12 | I33: 45077 | J33: Approved | K33: Petty Cash | L33: FY2023-2024 | N33: =IF(E33<0,"Credit/Refund","Expense") -> Expense | O33: =IF(AND(OR(J33="Pending",J33="Rejected"),E33>200000),"Flag: High-Value "&J33,"")
A34: EXP-00602 | B34: Unspecified | C34: Salaries | D34: Wipro | E34: 350446 | F34: 293167.5 | G34: =IF(F34="","",E34-F34) -> 57278.5 | H34: 57278.5 | I34: 45395 | J34: Approved | K34: Vendor Credit | L34: FY2024-2025 | N34: =IF(E34<0,"Credit/Refund","Expense") -> Expense | O34: =IF(AND(OR(J34="Pending",J34="Rejected"),E34>200000),"Flag: High-Value "&J34,"")
A35: EXP-00083 | B35: Support | C35: Maintenance | D35: Wipro | E35: 215496 | F35: 269360.68 | G35: =IF(F35="","",E35-F35) -> -53864.68 | I35: 45427 | J35: Rejected | K35: Petty Cash | L35: FY2024-2025 | M35: Duplicate entry | N35: =IF(E35<0,"Credit/Refund","Expense") -> Expense | O35: =IF(AND(OR(J35="Pending",J35="Rejected"),E35>200000),"Flag: High-Value "&J35,"") -> Flag: High-Value Rejected
A36: EXP-00750 | B36: Sales | C36: Recruitment | D36: Freshdesk | E36: 7227 | F36: 9023.9 | G36: =IF(F36="","",E36-F36) -> -1796.9 | H36: -1796.9 | I36: 45131 | J36: Approved | K36: Vendor Credit | L36: FY2023-2024 | N36: =IF(E36<0,"Credit/Refund","Expense") -> Expense | O36: =IF(AND(OR(J36="Pending",J36="Rejected"),E36>200000),"Flag: High-Value "&J36,"")
A37: EXP-00172 | B37: Operations | C37: Travel | D37: AWS | E37: 481644 | F37: 431586.58 | G37: =IF(F37="","",E37-F37) -> 50057.42 | H37: 50057.42 | I37: 45338 | J37: Approved | K37: Vendor Credit | L37: FY2023-2024 | M37: Urgent | N37: =IF(E37<0,"Credit/Refund","Expense") -> Expense | O37: =IF(AND(OR(J37="Pending",J37="Rejected"),E37>200000),"Flag: High-Value "&J37,"")
A38: EXP-00531 | B38: Sales | C38: Recruitment | D38: AWS | E38: -214583 | F38: 220195.61 | G38: =IF(F38="","",E38-F38) -> -434778.61 | H38: -5612.61 | I38: 45157 | J38: Approved | K38: Petty Cash | L38: FY2023-2024 | N38: =IF(E38<0,"Credit/Refund","Expense") -> Credit/Refund | O38: =IF(AND(OR(J38="Pending",J38="Rejected"),E38>200000),"Flag: High-Value "&J38,"")
A39: EXP-00337 | B39: Sales | C39: Utilities | D39: HubSpot | E39: 71717 | F39: 89231.77 | G39: =IF(F39="","",E39-F39) -> -17514.77 | H39: -17514.77 | I39: 45573 | J39: Approved | K39: Credit Card | L39: FY2024-2025 | M39: Urgent | N39: =IF(E39<0,"Credit/Refund","Expense") -> Expense | O39: =IF(AND(OR(J39="Pending",J39="Rejected"),E39>200000),"Flag: High-Value "&J39,"")
A40: EXP-00832 | B40: Engineering | C40: Training | D40: Infosys | E40: 352092 | F40: 424330.22 | G40: =IF(F40="","",E40-F40) -> -72238.22 | H40: -72238.22 | I40: 45540 | J40: Approved | K40: Bank Transfer | L40: FY2024-2025 | M40: One-time | N40: =IF(E40<0,"Credit/Refund","Expense") -> Expense | O40: =IF(AND(OR(J40="Pending",J40="Rejected"),E40>200000),"Flag: High-Value "&J40,"")
...

Sheet Sales Analysis
A1: Task/Case Study 2 — Part B: Sales Analysis
A2: NovaByte Solutions — source: Cleaned_Sales_Deals (2,500 deals after removing duplicates)
A4: 1. Total Deal Value and Deal Count by Deal Stage and Quarter
A5: Total Deal Value (INR) — all deals regardless of stage outcome
A6: Sum of Deal_Value_INR | B6: Column Labels
A7: Row Labels | B7: Q1-2023 | C7: Q1-2024 | D7: Q1-2025 | E7: Q2-2023 | F7: Q2-2024 | G7: Q3-2023 | H7: Q3-2024 | I7: Q4-2023 | J7: Q4-2024 | K7: Grand Total
A8: Closed Lost | B8: 9141005 | C8: 9689942 | D8: 11235371 | E8: 12418633 | F8: 11860603 | G8: 13566424 | H8: 11346226 | I8: 9339682 | J8: 9138527 | K8: 97736413
A9: Closed Won | B9: 23298342 | C9: 19839336 | D9: 15486634 | E9: 21194799 | F9: 13903057 | G9: 16417272 | H9: 17997739 | I9: 22994816 | J9: 17248504 | K9: 168380499
A10: Negotiation | B10: 12206699 | C10: 8752913 | D10: 11486069 | E10: 13861972 | F10: 10747999 | G10: 11427216 | H10: 13882593 | I10: 11154542 | J10: 11906162 | K10: 105426165
A11: Proposal Sent | B11: 15444405 | C11: 13171347 | D11: 19932319 | E11: 12101534 | F11: 17246961 | G11: 18600069 | H11: 14770864 | I11: 14497360 | J11: 12170242 | K11: 137935101
A12: Prospecting | B12: 6542137 | C12: 12292551 | D12: 8303277 | E12: 11244293 | F12: 7761452 | G12: 4429654 | H12: 8460044 | I12: 7564203 | J12: 6202016 | K12: 72799627
A13: Qualification | B13: 11504094 | C13: 13245808 | D13: 14278340 | E13: 14189296 | F13: 11142002 | G13: 10554962 | H13: 13217207 | I13: 10086169 | J13: 15644643 | K13: 113862521
A14: Grand Total | B14: 78136682 | C14: 76991897 | D14: 80722010 | E14: 85010527 | F14: 72662074 | G14: 74995597 | H14: 79674673 | I14: 75636772 | J14: 72310094 | K14: 696140326
A16: Deal Count by Stage and Quarter
A17: Count of Deal_ID | B17: Column Labels
A18: Row Labels | B18: Q1-2023 | C18: Q1-2024 | D18: Q1-2025 | E18: Q2-2023 | F18: Q2-2024 | G18: Q3-2023 | H18: Q3-2024 | I18: Q4-2023 | J18: Q4-2024 | K18: Grand Total
A19: Closed Lost | B19: 30 | C19: 39 | D19: 46 | E19: 44 | F19: 46 | G19: 44 | H19: 43 | I19: 36 | J19: 33 | K19: 361
A20: Closed Won | B20: 81 | C20: 69 | D20: 63 | E20: 79 | F20: 56 | G20: 60 | H20: 72 | I20: 83 | J20: 61 | K20: 624
A21: Negotiation | B21: 50 | C21: 38 | D21: 41 | E21: 52 | F21: 40 | G21: 42 | H21: 45 | I21: 39 | J21: 46 | K21: 393
A22: Proposal Sent | B22: 56 | C22: 42 | D22: 58 | E22: 44 | F22: 47 | G22: 62 | H22: 50 | I22: 55 | J22: 42 | K22: 456
A23: Prospecting | B23: 26 | C23: 32 | D23: 25 | E23: 42 | F23: 25 | G23: 19 | H23: 30 | I23: 28 | J23: 30 | K23: 257
A24: Qualification | B24: 43 | C24: 54 | D24: 49 | E24: 48 | F24: 42 | G24: 39 | H24: 42 | I24: 40 | J24: 52 | K24: 409
A25: Grand Total | B25: 286 | C25: 274 | D25: 282 | E25: 309 | F25: 256 | G25: 266 | H25: 282 | I25: 281 | J25: 264 | K25: 2500
A27: 2. Win Rate by Sales Rep and by Region
A28: Win Rate = Closed Won / (Closed Won + Closed Lost)
A29: By Sales Rep
A30: Sales_Rep | B30: Closed Won | C30: Closed Lost | D30: Total Closed | E30: Win Rate
A31: Aditya Pillai | B31: =COUNTIFS('Cleaned_Sales_Deals'!$B$2:$B$2501,$A31,'Cleaned_Sales_Deals'!$F$2:$F$2501,"Closed Won") -> 39 | C31: =COUNTIFS('Cleaned_Sales_Deals'!$B$2:$B$2501,$A31,'Cleaned_Sales_Deals'!$F$2:$F$2501,"Closed Lost") -> 24 | D31: =B31+C31 -> 63 | E31: =IF(B31+C31=0,0,B31/(B31+C31)) -> 0.61904762
A32: Amit Pillai | B32: =COUNTIFS('Cleaned_Sales_Deals'!$B$2:$B$2501,$A32,'Cleaned_Sales_Deals'!$F$2:$F$2501,"Closed Won") -> 39 | C32: =COUNTIFS('Cleaned_Sales_Deals'!$B$2:$B$2501,$A32,'Cleaned_Sales_Deals'!$F$2:$F$2501,"Closed Lost") -> 31 | D32: =B32+C32 -> 70 | E32: =IF(B32+C32=0,0,B32/(B32+C32)) -> 0.55714286
A33: Ananya Sharma | B33: =COUNTIFS('Cleaned_Sales_Deals'!$B$2:$B$2501,$A33,'Cleaned_Sales_Deals'!$F$2:$F$2501,"Closed Won") -> 39 | C33: =COUNTIFS('Cleaned_Sales_Deals'!$B$2:$B$2501,$A33,'Cleaned_Sales_Deals'!$F$2:$F$2501,"Closed Lost") -> 22 | D33: =B33+C33 -> 61 | E33: =IF(B33+C33=0,0,B33/(B33+C33)) -> 0.63934426
A34: Arjun Rao | B34: =COUNTIFS('Cleaned_Sales_Deals'!$B$2:$B$2501,$A34,'Cleaned_Sales_Deals'!$F$2:$F$2501,"Closed Won") -> 39 | C34: =COUNTIFS('Cleaned_Sales_Deals'!$B$2:$B$2501,$A34,'Cleaned_Sales_Deals'!$F$2:$F$2501,"Closed Lost") -> 16 | D34: =B34+C34 -> 55 | E34: =IF(B34+C34=0,0,B34/(B34+C34)) -> 0.70909091
A35: Deepika Das | B35: =COUNTIFS('Cleaned_Sales_Deals'!$B$2:$B$2501,$A35,'Cleaned_Sales_Deals'!$F$2:$F$2501,"Closed Won") -> 42 | C35: =COUNTIFS('Cleaned_Sales_Deals'!$B$2:$B$2501,$A35,'Cleaned_Sales_Deals'!$F$2:$F$2501,"Closed Lost") -> 27 | D35: =B35+C35 -> 69 | E35: =IF(B35+C35=0,0,B35/(B35+C35)) -> 0.60869565
A36: Meera Reddy | B36: =COUNTIFS('Cleaned_Sales_Deals'!$B$2:$B$2501,$A36,'Cleaned_Sales_Deals'!$F$2:$F$2501,"Closed Won") -> 34 | C36: =COUNTIFS('Cleaned_Sales_Deals'!$B$2:$B$2501,$A36,'Cleaned_Sales_Deals'!$F$2:$F$2501,"Closed Lost") -> 16 | D36: =B36+C36 -> 50 | E36: =IF(B36+C36=0,0,B36/(B36+C36)) -> 0.68
A37: Neha Pillai | B37: =COUNTIFS('Cleaned_Sales_Deals'!$B$2:$B$2501,$A37,'Cleaned_Sales_Deals'!$F$2:$F$2501,"Closed Won") -> 51 | C37: =COUNTIFS('Cleaned_Sales_Deals'!$B$2:$B$2501,$A37,'Cleaned_Sales_Deals'!$F$2:$F$2501,"Closed Lost") -> 23 | D37: =B37+C37 -> 74 | E37: =IF(B37+C37=0,0,B37/(B37+C37)) -> 0.68918919
A38: Priya Kumar | B38: =COUNTIFS('Cleaned_Sales_Deals'!$B$2:$B$2501,$A38,'Cleaned_Sales_Deals'!$F$2:$F$2501,"Closed Won") -> 32 | C38: =COUNTIFS('Cleaned_Sales_Deals'!$B$2:$B$2501,$A38,'Cleaned_Sales_Deals'!$F$2:$F$2501,"Closed Lost") -> 15 | D38: =B38+C38 -> 47 | E38: =IF(B38+C38=0,0,B38/(B38+C38)) -> 0.68085106
A39: Rahul Patel | B39: =COUNTIFS('Cleaned_Sales_Deals'!$B$2:$B$2501,$A39,'Cleaned_Sales_Deals'!$F$2:$F$2501,"Closed Won") -> 43 | C39: =COUNTIFS('Cleaned_Sales_Deals'!$B$2:$B$2501,$A39,'Cleaned_Sales_Deals'!$F$2:$F$2501,"Closed Lost") -> 30 | D39: =B39+C39 -> 73 | E39: =IF(B39+C39=0,0,B39/(B39+C39)) -> 0.5890411
A40: Riya Das | B40: =COUNTIFS('Cleaned_Sales_Deals'!$B$2:$B$2501,$A40,'Cleaned_Sales_Deals'!$F$2:$F$2501,"Closed Won") -> 49 | C40: =COUNTIFS('Cleaned_Sales_Deals'!$B$2:$B$2501,$A40,'Cleaned_Sales_Deals'!$F$2:$F$2501,"Closed Lost") -> 27 | D40: =B40+C40 -> 76 | E40: =IF(B40+C40=0,0,B40/(B40+C40)) -> 0.64473684
A41: Rohit Mehta | B41: =COUNTIFS('Cleaned_Sales_Deals'!$B$2:$B$2501,$A41,'Cleaned_Sales_Deals'!$F$2:$F$2501,"Closed Won") -> 35 | C41: =COUNTIFS('Cleaned_Sales_Deals'!$B$2:$B$2501,$A41,'Cleaned_Sales_Deals'!$F$2:$F$2501,"Closed Lost") -> 24 | D41: =B41+C41 -> 59 | E41: =IF(B41+C41=0,0,B41/(B41+C41)) -> 0.59322034
A42: Siddharth Gupta | B42: =COUNTIFS('Cleaned_Sales_Deals'!$B$2:$B$2501,$A42,'Cleaned_Sales_Deals'!$F$2:$F$2501,"Closed Won") -> 49 | C42: =COUNTIFS('Cleaned_Sales_Deals'!$B$2:$B$2501,$A42,'Cleaned_Sales_Deals'!$F$2:$F$2501,"Closed Lost") -> 26 | D42: =B42+C42 -> 75 | E42: =IF(B42+C42=0,0,B42/(B42+C42)) -> 0.65333333
... A46: Vikram Patel | B46: =COUNTIFS('Cleaned_Sales_Deals'!$B$2:$B$2501,$A46,'Cleaned_Sales_Deals'!$F$2:$F$2501,"Closed Won") -> 37 | C46: =COUNTIFS('Cleaned_Sales_Deals'!$B$2:$B$2501,$A46,'Cleaned_Sales_Deals'!$F$2:$F$2501,"Closed Lost") -> 26 | D46: =B46+C46 -> 63 | E46: =IF(B46+C46=0,0,B46/(B46+C46)) -> 0.58730159
...

Sheet Finance Analysis
A1: Task/Case Study 2 — Part C: Finance Analysis
A2: NovaByte Solutions — source: Cleaned_Finance_Expenses (1,000 expense records after removing duplicates)
A4: 1. Total Expenses by Department and Category (INR)
A5: Sum of Amount_INR | B5: Column Labels
A6: Row Labels | B6: Cloud Infrastructure | C6: Consulting Fees | D6: Hardware | E6: Maintenance | F6: Marketing Spend | G6: Office Supplies | H6: Recruitment | I6: Salaries | J6: Software Licenses | K6: Training | L6: Travel | M6: Uncategorized | N6: Utilities | O6: Grand Total
A7: Engineering | B7: 5795040 | C7: 1128531 | D7: 3993637 | E7: 924960 | F7: 3446437 | G7: 1300724 | H7: 2355469 | I7: 6370023 | J7: 2513074 | K7: 4206292 | L7: 4135341 | M7: 1255698 | N7: 2590417 | O7: 40015643
A8: Finance | B8: 3646108 | C8: 2209761 | D8: 6637640 | E8: 2277656 | F8: 2847110 | G8: 3964591 | H8: 1771627 | I8: 1313989 | J8: 2349527 | K8: 4061504 | L8: 3983167 | M8: 23074 | N8: 3384454 | O8: 38470208
A9: HR | B9: 4408964 | C9: 5374467 | D9: 7274449 | E9: 2421840 | F9: 3771312 | G9: 7827174 | H9: 2240911 | I9: 1804719 | J9: 1671108 | K9: 6664228 | L9: 3721454 | M9: 628123 | N9: 2867421 | O9: 50676170
A10: Marketing | B10: 7342425 | C10: 1718519 | D10: 9532434 | E10: 2628554 | F10: 2509466 | G10: 2124498 | H10: 2872365 | I10: 2990876 | J10: -1252981 | K10: 3159703 | L10: 2596005 | M10: 1411532 | N10: 2266604 | O10: 39900000
A11: Operations | B11: 1847947 | C11: 5774464 | D11: 4033017 | E11: 3546763 | F11: 9444775 | G11: 2253099 | H11: 5714184 | I11: 945965 | J11: 2739089 | K11: 2271507 | L11: 4032223 | M11: 1090934 | N11: 5834226 | O11: 49528193
A12: Sales | B12: 976653 | C12: 2578908 | D12: 2610012 | E12: 1445061 | F12: 4720848 | G12: 1531770 | H12: 2700212 | I12: 3760367 | J12: 1050435 | K12: 2724040 | L12: 3147054 | M12: 1846065 | N12: 2651718 | O12: 31743143
A13: Support | B13: 2537853 | C13: 4497678 | D13: 1838690 | E13: 7485990 | F13: 5863267 | G13: 2463145 | H13: 2560451 | I13: 3640812 | J13: 3557445 | K13: 2444307 | L13: 7563451 | M13: 328626 | N13: 2046375 | O13: 46828090
A14: Unspecified | B14: 919940 | C14: 620797 | D14: 981466 | E14: 242230 | F14: 435069 | G14: 305519 | H14: 568914 | I14: 1777305 | J14: 229898 | K14: 5333298 | L14: 2554546 | O14: 13968982
A15: Grand Total | B15: 27474930 | C15: 23903125 | D15: 36901345 | E15: 20973054 | F15: 33038284 | G15: 21770520 | H15: 20784133 | I15: 22604056 | J15: 12857595 | K15: 30864879 | L15: 31733241 | M15: 6584052 | N15: 21641215 | O15: 311130429
A18: 2. Budget Variance (Actual vs Allocated) by Department
A19: Variance = Actual - Allocated (signed Amount_INR used, so refunds/credits reduce net spend). Positive = over budget. See Summary sheet for a note on the source Variance_INR column's sign convention.
A20: Row Labels | B20: Total Actual (INR) | C20: Total Allocated (INR) | D20: Variance (INR) | E20: Variance % | F20: Status
A21: Engineering | B21: 40015643 | C21: 48530293 | D21: =B21-C21 -> -8514650.3 | E21: =IF(C21=0,"",D21/C21) -> -0.17545021 | F21: =IF(D21>0,"Over Budget","Under Budget") -> Under Budget
A22: Finance | B22: 38470208 | C22: 41478706 | D22: =B22-C22 -> -3008498.4 | E22: =IF(C22=0,"",D22/C22) -> -0.072531153 | F22: =IF(D22>0,"Over Budget","Under Budget") -> Under Budget
A23: HR | B23: 50676170 | C23: 51893822 | D23: =B23-C23 -> -1217652.5 | E23: =IF(C23=0,"",D23/C23) -> -0.023464305 | F23: =IF(D23>0,"Over Budget","Under Budget") -> Under Budget
A24: Marketing | B24: 39900000 | C24: 50187718 | D24: =B24-C24 -> -10287718 | E24: =IF(C24=0,"",D24/C24) -> -0.20498477 | F24: =IF(D24>0,"Over Budget","Under Budget") -> Under Budget
A25: Operations | B25: 49528193 | C25: 52465663 | D25: =B25-C25 -> -2937469.6 | E25: =IF(C25=0,"",D25/C25) -> -0.05598842 | F25: =IF(D25>0,"Over Budget","Under Budget") -> Under Budget
A26: Sales | B26: 31743143 | C26: 34940189 | D26: =B26-C26 -> -3197046.4 | E26: =IF(C26=0,"",D26/C26) -> -0.091500546 | F26: =IF(D26>0,"Over Budget","Under Budget") -> Under Budget
A27: Support | B27: 46828090 | C27: 47761845 | D27: =B27-C27 -> -933755.38 | E27: =IF(C27=0,"",D27/C27) -> -0.019550237 | F27: =IF(D27>0,"Over Budget","Under Budget") -> Under Budget
A28: Unspecified | B28: 13968982 | C28: 15563379 | D28: =B28-C28 -> -1594396.5 | E28: =IF(C28=0,"",D28/C28) -> -0.1024454 | F28: =IF(D28>0,"Over Budget","Under Budget") -> Under Budget
A31: 3. Top 5 Vendors by Total Spend
A32: Vendor | B32: Total Spend (INR) | C32: Count of Expense_ID
A33: Wipro | B33: 29086598 | C33: 76
A34: Zoom | B34: 26635414 | C34: 61
A35: TCS | B35: 23793501 | C35: 69
A36: AWS | B36: 22876465 | C36: 63
A37: Google Cloud | B37: 21667738 | C37: 58
A40: 4. Rejected or Pending Expenses Above INR 200,000
A41: 181 expense records match this criteria (also flagged live in Cleaned_Finance_Expenses, column O).
A42: Expense_ID | B42: Category | C42: Vendor | D42: Approval Status | E42: Expense Date | F42: Sum of Amount (INR)
A43: EXP-00208 | B43: Salaries | C43: Freshdesk | D43: Pending | E43: 45105 | F43: 4846353
A44: EXP-00936 | B44: Travel | C44: Jira | D44: Pending | E44: 45467 | F44: 4800245
A45: EXP-00105 | B45: Training | C45: Oracle | D45: Rejected | E45: 45012 | F45: 4688784
A46: EXP-00717 | B46: Office Supplies | C46: Internal | D46: Pending | E46: 45464 | F46: 3606815
A47: EXP-00876 | B47: Recruitment | C47: Wipro | D47: Pending | E47: 45154 | F47: 3110100
...
